Workbook

Sheet 개요작성 - 정비계획변경
C2: ■ 설 계 개 요 | J2: ■ 부대복리시설
C3: 사업명 | D3: 봉천14구역 주택재개발 정비사업 | J3: 구 분 | L3: 법적 설치기준 및 지침기준 | N3: 설치계획 | O3: 비고
C4: 대지위치 | D4: 서울특별시 관악구 봉천동 1-13번지 일대 | J4: 진입도로 | K4: =INDEX($J$94:$N$94,MATCH($D$69,$J$93:$N$93,1)) -> 1000~2000세대 미만 | N4: =INDEX($J$95:$N$95,MATCH($D$69,$J$93:$N$93,1)) -> 15
C5: 지역지구 | D5: 제3종 일반주거지역, 도시지역 | J5: 단지내도로 | K5: 폭 7m 이상 | N5: 7M도로
C6: 건축규모 | D6: 지상 27층 / | E6: 4 | J6: 관리사무소 | K6: =D69 -> 1571 | M6: =IF(D69>=50, ROUNDUP((10+(D69-50)*0.05),2), "해당없음") -> 86.05 | N6: 350 | O6: (방재실, MDF포함)
C7: 용도 | D7: 공동주택 및 부대복리시설, 근린생활시설 | J7: 경 비 실 | N7: 100
C8: 대 지 면 적 | D8: 사업면적 | F8: 74209.4 | G8: =ROUNDDOWN(F8*0.3025,2) -> 22448.34 | H8: =F8/$F$8 -> 1 | J8: 경 로 당 | K8: 주민공동시설 총량제 | L8: 1,500세대 이상 (서울시 주택조례) | M8: 500 | N8: 600
D9: 제외면적 | E9: 도 로 | F9: 9078 | G9: =ROUNDDOWN(F9*0.3025,2) -> 2746.09 | H9: =F9/$F$8 -> 0.12232952 | J9: 어린이집 | M9: 725 | N9: 1200
E10: 공 원 | F10: 5100 | G10: =ROUNDDOWN(F10*0.3025,2) -> 1542.75 | H10: =F10/$F$8 -> 0.068724447 | J10: 작은도서관 | M10: 298 | N10: 650
E11: 사회복지시설 | F11: 1000 | G11: =ROUNDDOWN(F11*0.3025,2) -> 302.5 | H11: =F11/$F$8 -> 0.013475382 | J11: 다함께돌봄센터 | L11: =IF(D69>=500,"500세대이상 의무설치", "해당없음") -> 500세대이상 의무설치 | M11: =IF(D69>=500,"66㎡ 이상", "해당없음") -> 66㎡ 이상 | N11: 100
E12: 공공청사 | F12: 250 | G12: =ROUNDDOWN(F12*0.3025,2) -> 75.62 | H12: =F12/$F$8 -> 0.0033688455 | J12: 주민공동시설 | N12: 5200
E13: 종교용지(3개소) | F13: =1039.4+1199.7+770 -> 3009.1 | G13: =ROUNDDOWN(F13*0.3025,2) -> 910.25 | H13: =F13/$F$8 -> 0.040548771 | J13: 스카이커뮤니티 | N13: 420
E14: 주택용지 | F14: 954.6 | G14: =ROUNDDOWN(F14*0.3025,2) -> 288.76 | H14: =F14/$F$8 -> 0.012863599 | J14: 지역공동시설 | N14: 500
J15: 주민운동시설(옥외) | L15: =IF(D69>=500,"500세대이상 의무설치", "해당없음") -> 500세대이상 의무설치 | N15: 800
E16: 소 계 | F16: =SUM(F9:F14) -> 19391.7 | G16: =ROUNDDOWN(F16*0.3025,2) -> 5865.98 | H16: =F16/$F$8 -> 0.26131056 | J16: 어린이놀이터(옥외) | L16: =IF(D69<100,"-해당없음-",IF(D69<300,"지역여건에 맞게 설치",IF(D69<1000,"200㎡+세대당 1㎡",IF(D69>1000,"500㎡+세대당 0.7㎡")))) -> 500㎡+세대당 0.7㎡ | M16: =500+(D69*0.7) -> 1599.7 | N16: =ROUNDUP(M16,-2)+100 -> 1700
D17: 실사용 대지면적 | F17: =F8-F16 -> 54817.7 | G17: =ROUNDDOWN(F17*0.3025,2) -> 16582.35 | H17: =F17/$F$8 -> 0.73868944 | J17: 총량검토 | K17: 500㎡+세대*2㎡이상 설치 | M17: =500+$D$69*2 -> 3642 | N17: =N8+N9+N10+N11+N12+N14+N15+N16 -> 10750 | O17: 총량제 면적 (관리사무소 제외)
C18: 연 면 적 | D18: 구 분 | F18: 계 획 | H18: 비 율 | J18: 조경시설 | K18: 대지면적 x 0.15 | M18: =F17*0.15 -> 8222.655 | N18: =ROUNDUP(M18,-2)+200 -> 8500
D19: 아파트 | E19: 지상 | F19: =J69+N13+N14 -> 146300.85 | G19: =ROUNDDOWN(F19*0.3025,2) -> 44256 | H19: =F19/$F$25 -> 0.98518527 | J19: 주차대수 | K19: 면적기준 | L19: 85㎡이하 전용/75 | M19: =ROUNDUP((D49*F49+D43*F43+D47*F47+D53*F53+D55*F55+D39*F39+D41*F41+D57*F57+D59*F59)/75,0) -> 1302 | N19: =D69*O19 -> 2827.8 | O19: 1.8
E20: 지하 | F20: =K69+M69+N6+N7+N8+N9+N10+N11+N12 -> 127967.6 | G20: =ROUNDDOWN(F20*0.3025,2) -> 38710.19 | L20: 85㎡초과 전용/65 | M20: =ROUNDUP((D61*F61+D63*F63+D65*F65)/65,0) -> 176
E21: 소계 | F21: =SUM(F19:F20) -> 274268.45 | G21: =ROUNDDOWN(F21*0.3025,2) -> 82966.2 | L21: 소 계 | M21: =SUM(M19:M20) -> 1478
D22: 근린생활시설 | E22: 지상 | F22: =M76 -> 2200 | G22: =ROUNDDOWN(F22*0.3025,2) -> 665.5 | H22: =F22/$F$25 -> 0.01481473 | K22: 세대기준 | L22: 세대당0.8대 (전용60㎡이하) | M22: =(D39+D41+D43+D47+D53+D55+D57)*0.8 -> 725.6
E23: 지하 | F23: =D103 -> 4640 | G23: =ROUNDDOWN(F23*0.3025,2) -> 1403.6 | L23: 세대당1대 (전용60㎡초과) | M23: =(D49+D59+D61+D63+D65)*1 -> 664
E24: 소계 | F24: =F22+F23 -> 6840 | G24: =ROUNDDOWN(F24*0.3025,2) -> 2069.1 | L24: 소 계 | M24: =SUM(M22:M23) -> 1389.6
D25: 합계 | E25: 지상 | F25: =F19+F22 -> 148500.85 | G25: =ROUNDDOWN(F25*0.3025,2) -> 44921.5 | H25: =F25/$F$25 -> 1 | K25: 근린생활시설 | L25: 134 | M25: =(I80+K80)/L25 -> 36.940299 | N25: =ROUNDUP(M25*O25,0) -> 45 | O25: 1.2
E26: 지하 | F26: =F20+F23 -> 132607.6 | G26: =ROUNDDOWN(F26*0.3025,2) -> 40113.79 | K26: 합 계 | M26: =SUM(M24+M25) -> 1426.5403 | N26: =SUM(N19+N25) -> 2872.8
E27: 합계 | F27: =F21+F24 -> 281108.45 | G27: =ROUNDDOWN(F27*0.3025,2) -> 85035.3
C28: 지침 최대연면적 | D28: 279559.49 | F28: =D28*1.05 -> 293537.46 | J28: 공공임대비율 | K28: 세대수 | L28: =D69-(P31*2) -> 1499 | M28: 0.15 | O28: =L28*M28 -> 224.85
C29: 건축면적 | D29: =9794.86+N7+I80 -> 14494.86 | G29: =ROUNDDOWN(D29*0.3025,2) -> 4384.69 | H29: 50 | K29: 임대주택 세대수의 30%이상 또는 세대수의 5%이상을 40㎡이하 계획 | O29: =D45 -> 225
C30: 건폐율 | D30: =D29/F17 -> 0.26441934
C31: 용적률 산정 연면적 | D31: =F25 -> 148500.85 | G31: =ROUNDDOWN(D31*0.3025,2) -> 44921.5 | H31: 예정법적용적률 | J31: 법적상한 소형주택 임대비율 | K31: =D32 -> 2.7089945 | L31: 2.5821 | M31: 2 | N31: =(K31-L31)/M31 -> 0.06344727 | O31: =N32 -> 3478.0334 | P31: =L33+L34 -> 36
C32: 용 적 율 | D32: =D31/F17 -> 2.7089945 | H32: 270.94 | L32: =F17 -> 54817.7 | M32: =N31 -> 0.06344727 | N32: =L32*M32 -> 3478.0334
C33: 세 대 수 | D33: =D69 -> 1571 | K33: =C48 -> 59 | L33: =D47 -> 18 | M33: =J47 -> 81.02 | N33: =L33*M33 -> 1458.36 | O33: =N33+N34 -> 3470.4
C34: 주차대수 | D34: =N26 -> 2872.8 | H34: =$N$19/$D$69 -> 1.8 | K34: =C50 -> 84 | L34: =D49 -> 18 | M34: =J49 -> 111.78 | N34: =L34*M34 -> 2012.04
C36: ■ 아파트 분양면적표
C37: 구 분 | D37: 세대수 | E37: 세대비 | F37: 주거전용 | G37: 주 거 공 용 면 적 | J37: 공급면적 | K37: 기타공용면적 | N37: 소 계 | O37: 계약면적 | P37: 비 고
G38: 벽체공용 | H38: 코어공용 | I38: 소 계 | K38: 기계,전기실 | L38: 부대복리시설 | M38: 지하주차장
C39: =ROUNDDOWN(J40,0) -> 16 | D39: 95 | E39: =D39/$D$69 -> 0.060471038 | F39: 39.96 | G39: =G53 -> 5.85 | H39: =H53 -> 8.91 | I39: =G39+H39 -> 14.76 | J39: =F39+I39 -> 54.72 | K39: =$K$69/$F$69*F39 -> 0.36664247 | L39: =$L$69/$F$69*F39 -> 3.3437793 | M39: =$M$69/$F$69*F39 -> 43.545246 | N39: =K39+L39+M39 -> 47.255668 | O39: =J39+N39 -> 101.97567 | P39: 공공임대 | R39: =D39+D41 -> 180
C40: 39 | F40: =ROUNDDOWN(F39*0.3025,2) -> 12.08 | G40: =ROUNDDOWN(G39*0.3025,2) -> 1.76 | H40: =ROUNDDOWN(H39*0.3025,2) -> 2.69 | I40: =ROUNDDOWN(I39*0.3025,2) -> 4.46 | J40: =ROUNDDOWN(J39*0.3025,2) -> 16.55 | K40: =ROUNDDOWN(K39*0.3025,2) -> 0.11 | L40: =ROUNDDOWN(L39*0.3025,2) -> 1.01 | M40: =ROUNDDOWN(M39*0.3025,2) -> 13.17 | ... O40: =ROUNDDOWN(O39*0.3025,2) -> 30.84
C41: =ROUNDDOWN(J42,0) -> 20 | D41: 85 | E41: =D41/$D$69 -> 0.054105665 | F41: 49.98 | G41: =G55 -> 6.85 | H41: =H55 -> 11.15 | I41: =G41+H41 -> 18 | J41: =I41+F41 -> 67.98 | K41: =$K$69/$F$69*F41 -> 0.45857835 | L41: =$L$69/$F$69*F41 -> 4.1822345 | M41: =$M$69/$F$69*F41 -> 54.46425 | N41: =N57 -> 70.942631 | O41: =J41+N41 -> 138.92263
C42: =ROUNDDOWN(F41,0) -> 49 | F42: =ROUNDDOWN(F41*0.3025,2) -> 15.11 | G42: =ROUNDDOWN(G41*0.3025,2) -> 2.07 | H42: =ROUNDDOWN(H41*0.3025,2) -> 3.37 | I42: =ROUNDDOWN(I41*0.3025,2) -> 5.44 | J42: =ROUNDDOWN(J41*0.3025,2) -> 20.56 | K42: =ROUNDDOWN(K41*0.3025,2) -> 0.13 | L42: =ROUNDDOWN(L41*0.3025,2) -> 1.26 | M42: =ROUNDDOWN(M41*0.3025,2) -> 16.47 | ... O42: =ROUNDDOWN(O41*0.3025,2) -> 42.02
...

Sheet 적용개요
G2: ■ 설 계 개 요 | N2: ■ 부대복리시설
G3: 사업명 | H3: 봉천14구역 주택재개발 정비사업 | N3: 구 분 | P3: 법적 설치기준 및 지침기준 | R3: 설치계획 | S3: 비고
G4: 대지위치 | H4: 서울특별시 관악구 봉천동 1-13번지 일대 | N4: 진입도로 | O4: =INDEX($N$96:$R$96,MATCH($H$71,$N$95:$R$95,1)) -> 1000~2000세대 미만 | R4: =INDEX($N$97:$R$97,MATCH($H$71,$N$95:$R$95,1)) -> 15
G5: 지역지구 | H5: 제3종 일반주거지역, 도시지역 | N5: 단지내도로 | O5: 폭 7m 이상 | R5: 7M도로
G6: 건축규모 | H6: 지상 27층 / | I6: 4 | N6: 관리사무소 | O6: =H71 -> 1571 | Q6: =IF(H71>=50, ROUNDUP((10+(H71-50)*0.05),2), "해당없음") -> 86.05 | R6: 350 | S6: (방재실, MDF포함)
G7: 용도 | H7: 공동주택 및 부대복리시설, 근린생활시설 | N7: 경 비 실 | R7: 100
G8: 대 지 면 적 | H8: 사업면적 | J8: 74209.4 | K8: =ROUNDDOWN(J8*0.3025,2) -> 22448.34 | L8: =J8/$J$8 -> 1 | N8: 경 로 당 | O8: 주민공동시설 총량제 | P8: 1,500세대 이상 (서울시 주택조례) | Q8: 500 | R8: 600
H9: 제외면적 | I9: 도 로 | J9: 9078 | K9: =ROUNDDOWN(J9*0.3025,2) -> 2746.09 | L9: =J9/$J$8 -> 0.12232952 | N9: 어린이집 | Q9: 725 | R9: 1200
I10: 공 원 | J10: 5100 | K10: =ROUNDDOWN(J10*0.3025,2) -> 1542.75 | L10: =J10/$J$8 -> 0.068724447 | N10: 작은도서관 | Q10: 298 | R10: 650
I11: 사회복지시설 | J11: 1000 | K11: =ROUNDDOWN(J11*0.3025,2) -> 302.5 | L11: =J11/$J$8 -> 0.013475382 | N11: 다함께돌봄센터 | P11: =IF(H71>=500,"500세대이상 의무설치", "해당없음") -> 500세대이상 의무설치 | Q11: =IF(H71>=500,"66㎡ 이상", "해당없음") -> 66㎡ 이상 | R11: 100
I12: 공공청사 | J12: 250 | K12: =ROUNDDOWN(J12*0.3025,2) -> 75.62 | L12: =J12/$J$8 -> 0.0033688455 | N12: 주민공동시설 | R12: 5200
I13: 종교용지(3개소) | J13: =1039.4+1199.7+770 -> 3009.1 | K13: =ROUNDDOWN(J13*0.3025,2) -> 910.25 | L13: =J13/$J$8 -> 0.040548771 | N13: 스카이커뮤니티 | R13: 420
I14: 주택용지 | J14: 954.6 | K14: =ROUNDDOWN(J14*0.3025,2) -> 288.76 | L14: =J14/$J$8 -> 0.012863599 | N14: 지역공동시설 | R14: 500
N15: 주민운동시설(옥외) | P15: =IF(H71>=500,"500세대이상 의무설치", "해당없음") -> 500세대이상 의무설치 | R15: 800
I16: 소 계 | J16: =SUM(J9:J14) -> 19391.7 | K16: =ROUNDDOWN(J16*0.3025,2) -> 5865.98 | L16: =J16/$J$8 -> 0.26131056 | N16: 어린이놀이터(옥외) | P16: =IF(H71<100,"-해당없음-",IF(H71<300,"지역여건에 맞게 설치",IF(H71<1000,"200㎡+세대당 1㎡",IF(H71>1000,"500㎡+세대당 0.7㎡")))) -> 500㎡+세대당 0.7㎡ | Q16: =500+(H71*0.7) -> 1599.7 | R16: =ROUNDUP(Q16,-2)+100 -> 1700
H17: 실사용 대지면적 | J17: =J8-J16 -> 54817.7 | K17: =ROUNDDOWN(J17*0.3025,2) -> 16582.35 | L17: =J17/$J$8 -> 0.73868944 | N17: 총량검토 | O17: 500㎡+세대*2㎡이상 설치 | Q17: =500+$H$71*2 -> 3642 | R17: =R8+R9+R10+R11+R12+R14+R15+R16 -> 10750 | S17: 총량제 면적 (관리사무소 제외)
G18: 연 면 적 | H18: 구 분 | J18: 계 획 | L18: 비 율 | N18: 조경시설 | O18: 대지면적 x 0.15 | Q18: =J17*0.15 -> 8222.655 | R18: =ROUNDUP(Q18,-2)+200 -> 8500
H19: 아파트 | I19: 지상 | J19: =N71+R13+R14 -> 146300.85 | K19: =ROUNDDOWN(J19*0.3025,2) -> 44256 | L19: =J19/$J$25 -> 0.98518527 | N19: 주차대수 | O19: 면적기준 | P19: 85㎡이하 전용/75 | Q19: =ROUNDUP((H49*J49+H43*J43+H47*J47+H53*J53+H55*J55+H39*J39+H41*J41+H57*J57+H59*J59+H61*J61)/75,0) -> 1302 | R19: =H71*S19 -> 2827.8 | S19: 1.8
I20: 지하 | J20: =O71+Q71+R6+R7+R8+R9+R10+R11+R12 -> 127967.6 | K20: =ROUNDDOWN(J20*0.3025,2) -> 38710.19 | P20: 85㎡초과 전용/65 | Q20: =ROUNDUP((H63*J63+H65*J65+H67*J67)/65,0) -> 176
I21: 소계 | J21: =SUM(J19:J20) -> 274268.45 | K21: =ROUNDDOWN(J21*0.3025,2) -> 82966.2 | P21: 소 계 | Q21: =SUM(Q19:Q20) -> 1478
H22: 근린생활시설 | I22: 지상 | J22: =Q78 -> 2200 | K22: =ROUNDDOWN(J22*0.3025,2) -> 665.5 | L22: =J22/$J$25 -> 0.01481473 | O22: 세대기준 | P22: 세대당0.8대 (전용60㎡이하) | Q22: =(H39+H41+H43+H47+H53+H55+H57)*0.8 -> 725.6
I23: 지하 | J23: =H105 -> 4640 | K23: =ROUNDDOWN(J23*0.3025,2) -> 1403.6 | P23: 세대당1대 (전용60㎡초과) | Q23: =(H49+H59+H63+H65+H67)*1 -> 654
I24: 소계 | J24: =J22+J23 -> 6840 | K24: =ROUNDDOWN(J24*0.3025,2) -> 2069.1 | P24: 소 계 | Q24: =SUM(Q22:Q23) -> 1379.6
H25: 합계 | I25: 지상 | J25: =J19+J22 -> 148500.85 | K25: =ROUNDDOWN(J25*0.3025,2) -> 44921.5 | L25: =J25/$J$25 -> 1 | O25: 근린생활시설 | P25: 134 | Q25: =(M82+O82)/P25 -> 36.940299 | R25: =ROUNDUP(Q25*S25,0) -> 45 | S25: 1.2
I26: 지하 | J26: =J20+J23 -> 132607.6 | K26: =ROUNDDOWN(J26*0.3025,2) -> 40113.79 | O26: 합 계 | Q26: =SUM(Q24+Q25) -> 1416.5403 | R26: =SUM(R19+R25) -> 2872.8
I27: 합계 | J27: =J21+J24 -> 281108.45 | K27: =ROUNDDOWN(J27*0.3025,2) -> 85035.3
G28: 지침 최대연면적 | H28: 279559.49 | J28: =H28*1.05 -> 293537.46 | N28: 공공임대비율 | O28: 세대수 | P28: =H71-(T31*2) -> 1499 | Q28: 0.15 | S28: =P28*Q28 -> 224.85
G29: 건축면적 | H29: 10250.69 | K29: =ROUNDDOWN(H29*0.3025,2) -> 3100.83 | L29: 50 | O29: 임대주택 세대수의 30%이상 또는 세대수의 5%이상을 40㎡이하 계획 | S29: =H45 -> 225
G30: 건폐율 | H30: =H29/J17 -> 0.18699599
G31: 용적률 산정 연면적 | H31: =J25 -> 148500.85 | K31: =ROUNDDOWN(H31*0.3025,2) -> 44921.5 | L31: 예정법적용적률 | N31: 법적상한 소형주택 임대비율 | O31: =H32 -> 2.7089945 | P31: 2.5821 | Q31: 2 | R31: =(O31-P31)/Q31 -> 0.06344727 | S31: =R32 -> 3478.0334 | T31: =P33+P34 -> 36
G32: 용 적 율 | H32: =H31/J17 -> 2.7089945 | L32: 270.94 | P32: =J17 -> 54817.7 | Q32: =R31 -> 0.06344727 | R32: =P32*Q32 -> 3478.0334
G33: 세 대 수 | H33: =H71 -> 1571 | O33: =G48 -> 59 | P33: =H47 -> 18 | Q33: =N47 -> 81.02 | R33: =P33*Q33 -> 1458.36 | S33: =R33+R34 -> 3470.4
G34: 주차대수 | H34: =R26 -> 2872.8 | L34: =$R$19/$H$71 -> 1.8 | O34: =G50 -> 84 | P34: =H49 -> 18 | Q34: =N49 -> 111.78 | R34: =P34*Q34 -> 2012.04
G36: ■ 아파트 분양면적표
B37: 구분 | C37: 기준 | D37: 계획 | E37: 비고 | G37: 구 분 | H37: 세대수 | I37: 세대비 | J37: 주거전용 | K37: 주 거 공 용 면 적 | N37: 공급면적 | O37: 기타공용면적 | R37: 소 계 | S37: 계약면적 | T37: 비 고
K38: 벽체공용 | L38: 코어공용 | M38: 소 계 | O38: 기계,전기실 | P38: 부대복리시설 | Q38: 지하주차장
B39: =G54 -> 39 | C39: 117 | D39: =H39+H53 -> 117 | E39: =D39-C39 -> 0 | G39: =ROUNDDOWN(N40,0) -> 16 | H39: 95 | I39: =H39/$H$71 -> 0.060471038 | J39: 39.96 | K39: =K53 -> 5.85 | L39: =L53 -> 8.91 | M39: =K39+L39 -> 14.76 | N39: =J39+M39 -> 54.72 | O39: =$O$71/$J$71*J39 -> 0.36664247 | P39: =$P$71/$J$71*J39 -> 3.3437793 | Q39: =$Q$71/$J$71*J39 -> 43.545246 | R39: =O39+P39+Q39 -> 47.255668 | S39: =N39+R39 -> 101.97567 | T39: 공공임대 | V39: =H39+H41 -> 180
G40: 39 | J40: =ROUNDDOWN(J39*0.3025,2) -> 12.08 | K40: =ROUNDDOWN(K39*0.3025,2) -> 1.76 | L40: =ROUNDDOWN(L39*0.3025,2) -> 2.69 | M40: =ROUNDDOWN(M39*0.3025,2) -> 4.46 | N40: =ROUNDDOWN(N39*0.3025,2) -> 16.55 | O40: =ROUNDDOWN(O39*0.3025,2) -> 0.11 | P40: =ROUNDDOWN(P39*0.3025,2) -> 1.01 | Q40: =ROUNDDOWN(Q39*0.3025,2) -> 13.17 | ... S40: =ROUNDDOWN(S39*0.3025,2) -> 30.84
B41: =G56 -> 49 | C41: 180 | D41: =H41+H55 -> 180 | E41: =D41-C41 -> 0 | G41: =ROUNDDOWN(N42,0) -> 20 | H41: 85 | I41: =H41/$H$71 -> 0.054105665 | J41: 49.98 | K41: =K55 -> 6.85 | L41: =L55 -> 11.15 | M41: =K41+L41 -> 18 | N41: =M41+J41 -> 67.98 | O41: =$O$71/$J$71*J41 -> 0.45857835 | P41: =$P$71/$J$71*J41 -> 4.1822345 | Q41: =$Q$71/$J$71*J41 -> 54.46425 | R41: =R57 -> 70.942631 | S41: =N41+R41 -> 138.92263
G42: =ROUNDDOWN(J41,0) -> 49 | J42: =ROUNDDOWN(J41*0.3025,2) -> 15.11 | K42: =ROUNDDOWN(K41*0.3025,2) -> 2.07 | L42: =ROUNDDOWN(L41*0.3025,2) -> 3.37 | M42: =ROUNDDOWN(M41*0.3025,2) -> 5.44 | N42: =ROUNDDOWN(N41*0.3025,2) -> 20.56 | O42: =ROUNDDOWN(O41*0.3025,2) -> 0.13 | P42: =ROUNDDOWN(P41*0.3025,2) -> 1.26 | Q42: =ROUNDDOWN(Q41*0.3025,2) -> 16.47 | ... S42: =ROUNDDOWN(S41*0.3025,2) -> 42.02
...

Sheet 설계개요(alt1)
G2: ■ 설 계 개 요 (alt1) | N2: ■ 부대복리시설
E3: 0.7 | G3: 사업명 | H3: 마포구 성산시영아파트 재건축정비사업 | N3: 구 분 | P3: 법적 설치기준 및 지침기준 | R3: 설치계획 | S3: 비고
E4: =J23/(J14*E3) -> 2.7720436 | G4: 대지위치 | H4: 서울특별시 마포구 성산동 446일대 | N4: 진입도로 | O4: =INDEX($N$103:$R$103,MATCH($H$78,$N$102:$R$102,1)) -> 2000세대 이상 | R4: =INDEX($N$104:$R$104,MATCH($H$78,$N$102:$R$102,1)) -> 20
G5: 지역지구 | H5: 제3종 일반주거지역 | N5: 단지내도로 | O5: 폭 7m 이상 | R5: 7M도로
G6: 건축규모 | H6: 지상 35층 / | I6: =ROUNDUP(E4,0) -> 3 | N6: 관리사무소 | O6: =H78 -> 4706 | Q6: =IF(H78>=50, ROUNDUP((10+(H78-50)*0.05),2), "해당없음") -> 242.8 | R6: 280 | S6: (방재실, MDF포함)
G7: 용도 | H7: 공동주택 및 부대복리시설, 근린생활시설 | N7: 경 비 실 | R7: 300
G8: 대 지 면 적 | H8: 사업면적 | J8: 182618.4 | K8: =ROUNDDOWN(J8*0.3025,2) -> 55242.06 | L8: =J8/$J$8 -> 1 | N8: 경 로 당 | O8: 주민공동시설 총량제 | P8: 1,500세대 이상 (서울시 주택조례) | Q8: 500 | R8: 1100
H9: 제외면적 | I9: 도로 | J9: 6830.9 | K9: =ROUNDDOWN(J9*0.3025,2) -> 2066.34 | L9: =J9/$J$8 -> 0.037405322 | N9: 어린이집 | Q9: 725 | R9: 1400
C10: 1000세대이상 | D10: 3 | E10: =$H$78*D10 -> 14118 | I10: 유치원 | J10: 1000 | K10: =ROUNDDOWN(J10*0.3025,2) -> 302.5 | L10: =J10/$J$8 -> 0.0054758995 | N10: 작은도서관 | Q10: 298 | R10: 650
I11: 공원 | J11: =H78*3 -> 14118 | K11: =ROUNDDOWN(J11*0.3025,2) -> 4270.69 | L11: =J11/$J$8 -> 0.077308749 | N11: 다함께돌봄센터 | P11: =IF(H78>=500,"500세대이상 의무설치", "해당없음") -> 500세대이상 의무설치 | Q11: =IF(H78>=500,"66㎡ 이상", "해당없음") -> 66㎡ 이상 | R11: 600
N12: 주민공동시설 | R12: 5500
I13: 소계 | J13: =SUM(J9:J12) -> 21948.9 | K13: =ROUNDDOWN(J13*0.3025,2) -> 6639.54 | L13: =J13/$J$8 -> 0.12018997 | N13: 주민운동시설(옥외) | P13: =IF(H78>=500,"500세대이상 의무설치", "해당없음") -> 500세대이상 의무설치 | R13: 3800
H14: 실사용 대지면적 | J14: =J8-J13 -> 160669.5 | K14: =ROUNDDOWN(J14*0.3025,2) -> 48602.52 | L14: =J14/$J$8 -> 0.87981003 | N14: 어린이놀이터(옥외) | P14: =IF(H78<100,"해당없음",IF(H78<300,"지역여건에 맞게 설치",IF(H78<1000,"200㎡+세대당 1㎡",IF(H78>1000,"500㎡+세대당 0.7㎡")))) -> 500㎡+세대당 0.7㎡ | Q14: =500+(H78*0.7) -> 3794.2 | R14: 3700
C15: 120698 | G15: 연 면 적 | H15: 구 분 | J15: 계 획 | L15: 비 율 | N15: 총량검토 | O15: (500㎡+세대당 x 2㎡) x 1.25이상 설치 | Q15: =500+($H$78*2)*1.25 -> 12265 | R15: =R8+R9+R10+R11+R12+R13+R14 -> 16750 | S15: 총량제 면적 (관리사무소 제외)
C16: 93504.3 | D16: =C16/C15 -> 0.77469635 | H16: 아파트 | I16: 지상 | J16: =N78+R8+R9+R7 -> 480773.66 | K16: =ROUNDDOWN(J16*0.3025,2) -> 145434.03 | L16: =J16/$J$22 -> 0.99751024 | N16: 조경시설 | O16: 대지면적 x 0.15 | Q16: =J14*0.15 -> 24100.425 | R16: =ROUNDUP(Q16,-2)+100 -> 24300 | V16: 주차대당
I17: 지하 | J17: =O78+Q78+R6+R10+R12+R11 -> 304558 | K17: =ROUNDDOWN(J17*0.3025,2) -> 92128.79 | N17: 유치원 | R17: 1000 | V17: 42
I18: 소계 | J18: =SUM(J16:J17) -> 785331.66 | K18: =ROUNDDOWN(J18*0.3025,2) -> 237562.82 | N18: 주차대수 | O18: 면적기준 | P18: 85㎡이하 전용/75 | Q18: =ROUNDUP((SUMPRODUCT(H36:H51,J36:J51)+SUMPRODUCT(H56:H63,J56:J63))/75,0) -> 4207 | R18: =H78*S18 -> 7059 | S18: 1.5
H19: 근린생활시설 | I19: 지상 | J19: =Q85 -> 1200 | K19: =ROUNDDOWN(J19*0.3025,2) -> 363 | L19: =J19/$J$22 -> 0.0024897626 | P19: 85㎡초과 전용/65 | Q19: =ROUNDUP((SUMPRODUCT(H64:H75,J64:J75))/65,0) -> 522
I20: 지하 | J20: =Q87 -> 7210 | K20: =ROUNDDOWN(J20*0.3025,2) -> 2181.02 | P20: 소 계 | Q20: =SUM(Q18:Q19) -> 4729
I21: 소계 | J21: =J19+J20 -> 8410 | K21: =ROUNDDOWN(J21*0.3025,2) -> 2544.02 | O21: 세대기준 | P21: 세대당0.8대(전용60㎡이하) | Q21: =(SUM(H36:H47)+SUM(H56:H59))*0.8 -> 1553.6
H22: 합계 | I22: 지상 | J22: =J16+J19 -> 481973.66 | K22: =ROUNDDOWN(J22*0.3025,2) -> 145797.03 | L22: =J22/$J$22 -> 1 | P22: 세대당1대(전용60㎡초과) | Q22: =(SUM(H48:H51)+SUM(H60:H75))*1 -> 2764
I23: 지하 | J23: =J17+J20 -> 311768 | K23: =ROUNDDOWN(J23*0.3025,2) -> 94309.82 | P23: 소 계 | Q23: =SUM(Q21:Q22) -> 4317.6
I24: 합계 | J24: =J18+J21 -> 793741.66 | K24: =ROUNDDOWN(J24*0.3025,2) -> 240106.85 | O24: 근린생활시설 | P24: 134 | Q24: =(M89+O89)/P24 -> 45.522388 | R24: =ROUNDUP(Q24*S24,0) -> 55 | S24: 1.2
O25: 합 계 | Q25: =Q20+Q24 -> 4774.5224 | R25: =SUM(R18+R24) -> 7114
G26: 건축면적 | H26: =J14*0.2842 -> 45662.272 | K26: =ROUNDDOWN(H26*0.3025,2) -> 13812.83 | L26: 50
G27: 건폐율 | H27: =H26/J14 -> 0.2842 | N27: 재건축 소택임대비율 | O27: =H29 -> 2.9997832 | P27: 2.5 | Q27: 2 | R27: =(O27-P27)/Q27 -> 0.24989158 | S27: =R28 -> 40149.955 | T27: =P29+P30+P31 -> 472
G28: 용적률 산정 연면적 | H28: =J22 -> 481973.66 | K28: =ROUNDDOWN(H28*0.3025,2) -> 145797.03 | L28: 법적상한용적률 ( 300% 이하 ) | P28: =J14 -> 160669.5 | Q28: =R27 -> 0.24989158 | R28: =P28*Q28 -> 40149.955
G29: 용 적 율 | H29: =H28/J14 -> 2.9997832 | O29: =G45 -> 49 | P29: =H42 -> 192 | Q29: =N42 -> 71.05 | R29: =P29*Q29 -> 13641.6 | S29: =R29+R30+R31 -> 40216.2 | V29: =S29-S27 -> 66.245
G30: 세 대 수 | H30: =H78 -> 4706 | O30: =G47 -> 59 | P30: =H46 -> 190 | Q30: =N46 -> 85.35 | R30: =P30*Q30 -> 16216.5
G31: 주차대수 | H31: =R25 -> 7114 | L31: =$R$18/$H$78 -> 1.5 | O31: =G51 -> 84 | P31: =H50 -> 90 | Q31: =N50 -> 115.09 | R31: =P31*Q31 -> 10358.1
G33: ■ 아파트 분양면적표
G34: 구 분 | H34: 세대수 | I34: 세대비 | J34: 주거전용 | K34: 주 거 공 용 면 적 | N34: 공급면적 | O34: 기타공용면적 | R34: 소 계 | S34: 계약면적 | T34: 비 고
K35: 벽체공용 | L35: 코어공용 | M35: 소 계 | O35: 기계,전기실 | P35: 부대복리시설 | Q35: 지하주차장
E36: =ROUNDUP(H78*0.05,0) -> 236 | F36: =H36/#REF! -> #REF! | G36: =ROUNDDOWN(N37,0) -> 17 | I36: =H36/$H$78 -> 0 | J36: =J54 -> 39.96 | K36: =K54 -> 3.65 | L36: =L54 -> 14.8 | M36: =K36+L36 -> 18.45 | N36: =J36+M36 -> 58.41 | O36: =$O$78/$J$78*J36 -> 0.12009731 | P36: =$P$78/$J$78*J36 -> 1.1243396 | Q36: =$Q$78/$J$78*J36 -> 33.910676 | R36: =O36+P36+Q36 -> 35.155113 | S36: =N36+R36 -> 93.565113 | T36: 의무임대
G37: 39 | J37: =ROUNDDOWN(J36*0.3025,2) -> 12.08 | K37: =ROUNDDOWN(K36*0.3025,2) -> 1.1 | L37: =ROUNDDOWN(L36*0.3025,2) -> 4.47 | M37: =ROUNDDOWN(M36*0.3025,2) -> 5.58 | N37: =ROUNDDOWN(N36*0.3025,2) -> 17.66 | O37: =ROUNDDOWN(O36*0.3025,2) -> 0.03 | P37: =ROUNDDOWN(P36*0.3025,2) -> 0.34 | Q37: =ROUNDDOWN(Q36*0.3025,2) -> 10.25 | ... S37: =ROUNDDOWN(S36*0.3025,2) -> 28.3
F38: =H38/#REF! -> #REF! | G38: =ROUNDDOWN(N39,0) -> 21 | I38: =H38/$H$78 -> 0 | J38: =J56 -> 49.95 | K38: =K56 -> 4.5 | L38: =L56 -> 16.6 | M38: =K38+L38 -> 21.1 | N38: =M38+J38 -> 71.05 | O38: =$O$78/$J$78*J38 -> 0.15012163 | P38: =$P$78/$J$78*J38 -> 1.4054244 | Q38: =$Q$78/$J$78*J38 -> 42.388345 | R38: =O38+P38+Q38 -> 43.943891 | S38: =N38+R38 -> 114.99389
G39: =ROUNDDOWN(J38,0) -> 49 | J39: =ROUNDDOWN(J38*0.3025,2) -> 15.1 | K39: =ROUNDDOWN(K38*0.3025,2) -> 1.36 | L39: =ROUNDDOWN(L38*0.3025,2) -> 5.02 | M39: =ROUNDDOWN(M38*0.3025,2) -> 6.38 | N39: =ROUNDDOWN(N38*0.3025,2) -> 21.49 | O39: =ROUNDDOWN(O38*0.3025,2) -> 0.04 | P39: =ROUNDDOWN(P38*0.3025,2) -> 0.42 | Q39: =ROUNDDOWN(Q38*0.3025,2) -> 12.82 | ... S39: =ROUNDDOWN(S38*0.3025,2) -> 34.78
F40: =H40/#REF! -> #REF! | G40: =ROUNDDOWN(N41,0) -> 25 | I40: =H40/$H$78 -> 0 | J40: =J58 -> 59.95 | K40: =K58 -> 5.8 | L40: =L58 -> 19.6 | M40: =K40+L40 -> 25.4 | N40: =M40+J40 -> 85.35 | O40: =$O$78/$J$78*J40 -> 0.18017602 | P40: =$P$78/$J$78*J40 -> 1.6867907 | Q40: =$Q$78/$J$78*J40 -> 50.8745 | R40: =O40+P40+Q40 -> 52.741466 | S40: =N40+R40 -> 138.09147
G41: =ROUNDDOWN(J40,0) -> 59 | J41: =ROUNDDOWN(J40*0.3025,2) -> 18.13 | K41: =ROUNDDOWN(K40*0.3025,2) -> 1.75 | L41: =ROUNDDOWN(L40*0.3025,2) -> 5.92 | M41: =ROUNDDOWN(M40*0.3025,2) -> 7.68 | N41: =ROUNDDOWN(N40*0.3025,2) -> 25.81 | O41: =ROUNDDOWN(O40*0.3025,2) -> 0.05 | P41: =ROUNDDOWN(P40*0.3025,2) -> 0.51 | Q41: =ROUNDDOWN(Q40*0.3025,2) -> 15.38 | ... S41: =ROUNDDOWN(S40*0.3025,2) -> 41.77
E42: =H42/$H$52 -> 0.40677966 | G42: =ROUNDDOWN(N43,0) -> 21 | H42: 192 | I42: =H42/$H$78 -> 0.04079898 | J42: =J56 -> 49.95 | K42: =K56 -> 4.5 | L42: =L56 -> 16.6 | M42: =K42+L42 -> 21.1 | N42: =M42+J42 -> 71.05 | O42: =$O$78/$J$78*J42 -> 0.15012163 | P42: =$P$78/$J$78*J42 -> 1.4054244 | Q42: =$Q$78/$J$78*J42 -> 42.388345 | R42: =O42+P42+Q42 -> 43.943891 | S42: =N42+R42 -> 114.99389 | T42: 임대
...

Sheet 설계개요(alt2)
G2: ■ 설 계 개 요 (alt2) | N2: ■ 부대복리시설
E3: 0.7 | G3: 사업명 | H3: 마포구 성산시영아파트 재건축정비사업 | N3: 구 분 | P3: 법적 설치기준 및 지침기준 | R3: 설치계획 | S3: 비고
E4: =J23/(J14*E3) -> 2.7506405 | G4: 대지위치 | H4: 서울특별시 마포구 성산동 446일대 | N4: 진입도로 | O4: =INDEX($N$103:$R$103,MATCH($H$78,$N$102:$R$102,1)) -> 2000세대 이상 | R4: =INDEX($N$104:$R$104,MATCH($H$78,$N$102:$R$102,1)) -> 20
G5: 지역지구 | H5: 제3종 일반주거지역 | N5: 단지내도로 | O5: 폭 7m 이상 | R5: 7M도로
G6: 건축규모 | H6: 지상 35층 / | I6: =ROUNDUP(E4,0) -> 3 | N6: 관리사무소 | O6: =H78 -> 4671 | Q6: =IF(H78>=50, ROUNDUP((10+(H78-50)*0.05),2), "해당없음") -> 241.05 | R6: 280 | S6: (방재실, MDF포함)
G7: 용도 | H7: 공동주택 및 부대복리시설, 근린생활시설 | N7: 경 비 실 | R7: 300
G8: 대 지 면 적 | H8: 사업면적 | J8: 182618.4 | K8: =ROUNDDOWN(J8*0.3025,2) -> 55242.06 | L8: =J8/$J$8 -> 1 | N8: 경 로 당 | O8: 주민공동시설 총량제 | P8: 1,500세대 이상 (서울시 주택조례) | Q8: 500 | R8: 1100
H9: 제외면적 | I9: 도로 | J9: 6830.9 | K9: =ROUNDDOWN(J9*0.3025,2) -> 2066.34 | L9: =J9/$J$8 -> 0.037405322 | N9: 어린이집 | Q9: 725 | R9: 1400
C10: 1000세대이상 | D10: 3 | E10: =$H$78*D10 -> 14013 | I10: 유치원 | J10: 1000 | K10: =ROUNDDOWN(J10*0.3025,2) -> 302.5 | L10: =J10/$J$8 -> 0.0054758995 | N10: 작은도서관 | Q10: 298 | R10: 650
I11: 공원 | J11: =H78*3 -> 14013 | K11: =ROUNDDOWN(J11*0.3025,2) -> 4238.93 | L11: =J11/$J$8 -> 0.076733779 | N11: 다함께돌봄센터 | P11: =IF(H78>=500,"500세대이상 의무설치", "해당없음") -> 500세대이상 의무설치 | Q11: =IF(H78>=500,"66㎡ 이상", "해당없음") -> 66㎡ 이상 | R11: 600
N12: 주민공동시설 | R12: 5500
I13: 소계 | J13: =SUM(J9:J12) -> 21843.9 | K13: =ROUNDDOWN(J13*0.3025,2) -> 6607.77 | L13: =J13/$J$8 -> 0.119615 | N13: 주민운동시설(옥외) | P13: =IF(H78>=500,"500세대이상 의무설치", "해당없음") -> 500세대이상 의무설치 | R13: 3800
H14: 실사용 대지면적 | J14: =J8-J13 -> 160774.5 | K14: =ROUNDDOWN(J14*0.3025,2) -> 48634.28 | L14: =J14/$J$8 -> 0.880385 | N14: 어린이놀이터(옥외) | P14: =IF(H78<100,"해당없음",IF(H78<300,"지역여건에 맞게 설치",IF(H78<1000,"200㎡+세대당 1㎡",IF(H78>1000,"500㎡+세대당 0.7㎡")))) -> 500㎡+세대당 0.7㎡ | Q14: =500+(H78*0.7) -> 3769.7 | R14: 3700
C15: 120698 | G15: 연 면 적 | H15: 구 분 | J15: 계 획 | L15: 비 율 | N15: 총량검토 | O15: (500㎡+세대당 x 2㎡) x 1.25이상 설치 | Q15: =500+($H$78*2)*1.25 -> 12177.5 | R15: =R8+R9+R10+R11+R12+R13+R14 -> 16750 | S15: 총량제 면적 (관리사무소 제외)
C16: 93504.3 | D16: =C16/C15 -> 0.77469635 | H16: 아파트 | I16: 지상 | J16: =N78+R8+R9+R7 -> 481051.95 | K16: =ROUNDDOWN(J16*0.3025,2) -> 145518.21 | L16: =J16/$J$22 -> 0.99751167 | N16: 조경시설 | O16: 대지면적 x 0.15 | Q16: =J14*0.15 -> 24116.175 | R16: =ROUNDUP(Q16,-2)+100 -> 24300 | V16: 주차대당
I17: 지하 | J17: =O78+Q78+R6+R10+R12+R11 -> 302353 | K17: =ROUNDDOWN(J17*0.3025,2) -> 91461.78 | N17: 유치원 | R17: 1000 | V17: 42
I18: 소계 | J18: =SUM(J16:J17) -> 783404.95 | K18: =ROUNDDOWN(J18*0.3025,2) -> 236979.99 | N18: 주차대수 | O18: 면적기준 | P18: 85㎡이하 전용/75 | Q18: =ROUNDUP((SUMPRODUCT(H36:H51,J36:J51)+SUMPRODUCT(H56:H63,J56:J63))/75,0) -> 4208 | R18: =H78*S18 -> 7006.5 | S18: 1.5
H19: 근린생활시설 | I19: 지상 | J19: =Q85 -> 1200 | K19: =ROUNDDOWN(J19*0.3025,2) -> 363 | L19: =J19/$J$22 -> 0.0024883259 | P19: 85㎡초과 전용/65 | Q19: =ROUNDUP((SUMPRODUCT(H64:H75,J64:J75))/65,0) -> 522
I20: 지하 | J20: =Q87 -> 7210 | K20: =ROUNDDOWN(J20*0.3025,2) -> 2181.02 | P20: 소 계 | Q20: =SUM(Q18:Q19) -> 4730
I21: 소계 | J21: =J19+J20 -> 8410 | K21: =ROUNDDOWN(J21*0.3025,2) -> 2544.02 | O21: 세대기준 | P21: 세대당0.8대(전용60㎡이하) | Q21: =(SUM(H36:H47)+SUM(H56:H59))*0.8 -> 1544.8
H22: 합계 | I22: 지상 | J22: =J16+J19 -> 482251.95 | K22: =ROUNDDOWN(J22*0.3025,2) -> 145881.21 | L22: =J22/$J$22 -> 1 | P22: 세대당1대(전용60㎡초과) | Q22: =(SUM(H48:H51)+SUM(H60:H75))*1 -> 2740
I23: 지하 | J23: =J17+J20 -> 309563 | K23: =ROUNDDOWN(J23*0.3025,2) -> 93642.8 | P23: 소 계 | Q23: =SUM(Q21:Q22) -> 4284.8
I24: 합계 | J24: =J18+J21 -> 791814.95 | K24: =ROUNDDOWN(J24*0.3025,2) -> 239524.02 | O24: 근린생활시설 | P24: 134 | Q24: =(M89+O89)/P24 -> 45.522388 | R24: =ROUNDUP(Q24*S24,0) -> 55 | S24: 1.2
O25: 합 계 | Q25: =Q20+Q24 -> 4775.5224 | R25: =SUM(R18+R24) -> 7061.5
G26: 건축면적 | H26: =J14*0.2842 -> 45692.113 | K26: =ROUNDDOWN(H26*0.3025,2) -> 13821.86 | L26: 50
G27: 건폐율 | H27: =H26/J14 -> 0.2842 | N27: 재건축 소택임대비율 | O27: =H29 -> 2.999555 | P27: 2.5 | Q27: 2 | R27: =(O27-P27)/Q27 -> 0.24977748 | S27: =R28 -> 40157.85 | T27: =P29+P30+P31 -> 472
G28: 용적률 산정 연면적 | H28: =J22 -> 482251.95 | K28: =ROUNDDOWN(H28*0.3025,2) -> 145881.21 | L28: 법적상한용적률 ( 300% 이하 ) | P28: =J14 -> 160774.5 | Q28: =R27 -> 0.24977748 | R28: =P28*Q28 -> 40157.85
G29: 용 적 율 | H29: =H28/J14 -> 2.999555 | O29: =G45 -> 49 | P29: =H42 -> 192 | Q29: =N42 -> 71.05 | R29: =P29*Q29 -> 13641.6 | S29: =R29+R30+R31 -> 40216.2 | V29: =S29-S27 -> 58.35
G30: 세 대 수 | H30: =H78 -> 4671 | O30: =G47 -> 59 | P30: =H46 -> 190 | Q30: =N46 -> 85.35 | R30: =P30*Q30 -> 16216.5
G31: 주차대수 | H31: =R25 -> 7061.5 | L31: =$R$18/$H$78 -> 1.5 | O31: =G51 -> 84 | P31: =H50 -> 90 | Q31: =N50 -> 115.09 | R31: =P31*Q31 -> 10358.1
G33: ■ 아파트 분양면적표
G34: 구 분 | H34: 세대수 | I34: 세대비 | J34: 주거전용 | K34: 주 거 공 용 면 적 | N34: 공급면적 | O34: 기타공용면적 | R34: 소 계 | S34: 계약면적 | T34: 비 고
K35: 벽체공용 | L35: 코어공용 | M35: 소 계 | O35: 기계,전기실 | P35: 부대복리시설 | Q35: 지하주차장
E36: =ROUNDUP(H78*0.05,0) -> 234 | F36: =H36/#REF! -> #REF! | G36: =ROUNDDOWN(N37,0) -> 17 | I36: =H36/$H$78 -> 0 | J36: =J54 -> 39.96 | K36: =K54 -> 3.65 | L36: =L54 -> 14.8 | M36: =K36+L36 -> 18.45 | N36: =J36+M36 -> 58.41 | O36: =$O$78/$J$78*J36 -> 0.12006638 | P36: =$P$78/$J$78*J36 -> 1.12405 | Q36: =$Q$78/$J$78*J36 -> 33.649803 | R36: =O36+P36+Q36 -> 34.893919 | S36: =N36+R36 -> 93.303919 | T36: 의무임대
G37: 39 | J37: =ROUNDDOWN(J36*0.3025,2) -> 12.08 | K37: =ROUNDDOWN(K36*0.3025,2) -> 1.1 | L37: =ROUNDDOWN(L36*0.3025,2) -> 4.47 | M37: =ROUNDDOWN(M36*0.3025,2) -> 5.58 | N37: =ROUNDDOWN(N36*0.3025,2) -> 17.66 | O37: =ROUNDDOWN(O36*0.3025,2) -> 0.03 | P37: =ROUNDDOWN(P36*0.3025,2) -> 0.34 | Q37: =ROUNDDOWN(Q36*0.3025,2) -> 10.17 | ... S37: =ROUNDDOWN(S36*0.3025,2) -> 28.22
F38: =H38/#REF! -> #REF! | G38: =ROUNDDOWN(N39,0) -> 21 | I38: =H38/$H$78 -> 0 | J38: =J56 -> 49.95 | K38: =K56 -> 4.5 | L38: =L56 -> 16.6 | M38: =K38+L38 -> 21.1 | N38: =M38+J38 -> 71.05 | O38: =$O$78/$J$78*J38 -> 0.15008297 | P38: =$P$78/$J$78*J38 -> 1.4050625 | Q38: =$Q$78/$J$78*J38 -> 42.062254 | R38: =O38+P38+Q38 -> 43.617399 | S38: =N38+R38 -> 114.6674
G39: =ROUNDDOWN(J38,0) -> 49 | J39: =ROUNDDOWN(J38*0.3025,2) -> 15.1 | K39: =ROUNDDOWN(K38*0.3025,2) -> 1.36 | L39: =ROUNDDOWN(L38*0.3025,2) -> 5.02 | M39: =ROUNDDOWN(M38*0.3025,2) -> 6.38 | N39: =ROUNDDOWN(N38*0.3025,2) -> 21.49 | O39: =ROUNDDOWN(O38*0.3025,2) -> 0.04 | P39: =ROUNDDOWN(P38*0.3025,2) -> 0.42 | Q39: =ROUNDDOWN(Q38*0.3025,2) -> 12.72 | ... S39: =ROUNDDOWN(S38*0.3025,2) -> 34.68
F40: =H40/#REF! -> #REF! | G40: =ROUNDDOWN(N41,0) -> 25 | I40: =H40/$H$78 -> 0 | J40: =J58 -> 59.95 | K40: =K58 -> 5.8 | L40: =L58 -> 19.6 | M40: =K40+L40 -> 25.4 | N40: =M40+J40 -> 85.35 | O40: =$O$78/$J$78*J40 -> 0.18012961 | P40: =$P$78/$J$78*J40 -> 1.6863563 | Q40: =$Q$78/$J$78*J40 -> 50.483125 | R40: =O40+P40+Q40 -> 52.349611 | S40: =N40+R40 -> 137.69961
G41: =ROUNDDOWN(J40,0) -> 59 | J41: =ROUNDDOWN(J40*0.3025,2) -> 18.13 | K41: =ROUNDDOWN(K40*0.3025,2) -> 1.75 | L41: =ROUNDDOWN(L40*0.3025,2) -> 5.92 | M41: =ROUNDDOWN(M40*0.3025,2) -> 7.68 | N41: =ROUNDDOWN(N40*0.3025,2) -> 25.81 | O41: =ROUNDDOWN(O40*0.3025,2) -> 0.05 | P41: =ROUNDDOWN(P40*0.3025,2) -> 0.51 | Q41: =ROUNDDOWN(Q40*0.3025,2) -> 15.27 | ... S41: =ROUNDDOWN(S40*0.3025,2) -> 41.65
E42: =H42/$H$52 -> 0.40677966 | G42: =ROUNDDOWN(N43,0) -> 21 | H42: 192 | I42: =H42/$H$78 -> 0.041104689 | J42: =J56 -> 49.95 | K42: =K56 -> 4.5 | L42: =L56 -> 16.6 | M42: =K42+L42 -> 21.1 | N42: =M42+J42 -> 71.05 | O42: =$O$78/$J$78*J42 -> 0.15008297 | P42: =$P$78/$J$78*J42 -> 1.4050625 | Q42: =$Q$78/$J$78*J42 -> 42.062254 | R42: =O42+P42+Q42 -> 43.617399 | S42: =N42+R42 -> 114.6674 | T42: 임대
...

Sheet 설계개요(alt2) (j)
G2: ■ 설 계 개 요 (alt3) | N2: ■ 부대복리시설
E3: 0.7 | G3: 사업명 | H3: 마포구 성산시영아파트 재건축정비사업 | N3: 구 분 | P3: 법적 설치기준 및 지침기준 | R3: 설치계획 | S3: 비고
E4: =J23/(J14*E3) -> 2.8278227 | G4: 대지위치 | H4: 서울특별시 마포구 성산동 446일대 | N4: 진입도로 | O4: =INDEX($N$103:$R$103,MATCH($H$78,$N$102:$R$102,1)) -> 2000세대 이상 | R4: =INDEX($N$104:$R$104,MATCH($H$78,$N$102:$R$102,1)) -> 20
G5: 지역지구 | H5: 제3종 일반주거지역 | N5: 단지내도로 | O5: 폭 7m 이상 | R5: 7M도로
G6: 건축규모 | H6: 지상 35층 / | I6: =ROUNDUP(E4,0) -> 3 | N6: 관리사무소 | O6: =H78 -> 4797 | Q6: =IF(H78>=50, ROUNDUP((10+(H78-50)*0.05),2), "해당없음") -> 247.35 | R6: 280 | S6: (방재실, MDF포함)
G7: 용도 | H7: 공동주택 및 부대복리시설, 근린생활시설 | N7: 경 비 실 | R7: 300
G8: 대 지 면 적 | H8: 사업면적 | J8: 182618.4 | K8: =ROUNDDOWN(J8*0.3025,2) -> 55242.06 | L8: =J8/$J$8 -> 1 | N8: 경 로 당 | O8: 주민공동시설 총량제 | P8: 1,500세대 이상 (서울시 주택조례) | Q8: 500 | R8: 1100
H9: 제외면적 | I9: 도로 | J9: 6830.9 | K9: =ROUNDDOWN(J9*0.3025,2) -> 2066.34 | L9: =J9/$J$8 -> 0.037405322 | N9: 어린이집 | Q9: 725 | R9: 1400
C10: 1000세대이상 | D10: 3 | E10: =$H$78*D10 -> 14391 | I10: 유치원 | J10: 1000 | K10: =ROUNDDOWN(J10*0.3025,2) -> 302.5 | L10: =J10/$J$8 -> 0.0054758995 | N10: 작은도서관 | Q10: 298 | R10: 650
I11: 공원 | J11: =H78*3 -> 14391 | K11: =ROUNDDOWN(J11*0.3025,2) -> 4353.27 | L11: =J11/$J$8 -> 0.078803669 | N11: 다함께돌봄센터 | P11: =IF(H78>=500,"500세대이상 의무설치", "해당없음") -> 500세대이상 의무설치 | Q11: =IF(H78>=500,"66㎡ 이상", "해당없음") -> 66㎡ 이상 | R11: 600
N12: 주민공동시설 | R12: 5500
I13: 소계 | J13: =SUM(J9:J12) -> 22221.9 | K13: =ROUNDDOWN(J13*0.3025,2) -> 6722.12 | L13: =J13/$J$8 -> 0.12168489 | N13: 주민운동시설(옥외) | P13: =IF(H78>=500,"500세대이상 의무설치", "해당없음") -> 500세대이상 의무설치 | R13: 3800
H14: 실사용 대지면적 | J14: =J8-J13 -> 160396.5 | K14: =ROUNDDOWN(J14*0.3025,2) -> 48519.94 | L14: =J14/$J$8 -> 0.87831511 | N14: 어린이놀이터(옥외) | P14: =IF(H78<100,"해당없음",IF(H78<300,"지역여건에 맞게 설치",IF(H78<1000,"200㎡+세대당 1㎡",IF(H78>1000,"500㎡+세대당 0.7㎡")))) -> 500㎡+세대당 0.7㎡ | Q14: =500+(H78*0.7) -> 3857.9 | R14: 3700
C15: 120698 | G15: 연 면 적 | H15: 구 분 | J15: 계 획 | L15: 비 율 | N15: 총량검토 | O15: (500㎡+세대당 x 2㎡) x 1.25이상 설치 | Q15: =500+($H$78*2)*1.25 -> 12492.5 | R15: =R8+R9+R10+R11+R12+R13+R14 -> 16750 | S15: 총량제 면적 (관리사무소 제외)
C16: 93504.3 | D16: =C16/C15 -> 0.77469635 | H16: 아파트 | I16: 지상 | J16: =N78+R8+R9+R7 -> 479809.63 | K16: =ROUNDDOWN(J16*0.3025,2) -> 145142.41 | L16: =J16/$J$22 -> 0.99750525 | N16: 조경시설 | O16: 대지면적 x 0.15 | Q16: =J14*0.15 -> 24059.475 | R16: =ROUNDUP(Q16,-2)+100 -> 24200 | V16: 주차대당
I17: 지하 | J17: =O78+Q78+R6+R10+R12+R11 -> 310291 | K17: =ROUNDDOWN(J17*0.3025,2) -> 93863.02 | N17: 유치원 | R17: 1000 | V17: 42
I18: 소계 | J18: =SUM(J16:J17) -> 790100.63 | K18: =ROUNDDOWN(J18*0.3025,2) -> 239005.44 | N18: 주차대수 | O18: 면적기준 | P18: 85㎡이하 전용/75 | Q18: =ROUNDUP((SUMPRODUCT(H36:H51,J36:J51)+SUMPRODUCT(H56:H63,J56:J63))/75,0) -> 4206 | R18: =H78*S18 -> 7195.5 | S18: 1.5
H19: 근린생활시설 | I19: 지상 | J19: =Q85 -> 1200 | K19: =ROUNDDOWN(J19*0.3025,2) -> 363 | L19: =J19/$J$22 -> 0.0024947525 | P19: 85㎡초과 전용/65 | Q19: =ROUNDUP((SUMPRODUCT(H64:H75,J64:J75))/65,0) -> 494
I20: 지하 | J20: =Q87 -> 7210 | K20: =ROUNDDOWN(J20*0.3025,2) -> 2181.02 | P20: 소 계 | Q20: =SUM(Q18:Q19) -> 4700
I21: 소계 | J21: =J19+J20 -> 8410 | K21: =ROUNDDOWN(J21*0.3025,2) -> 2544.02 | O21: 세대기준 | P21: 세대당0.8대(전용60㎡이하) | Q21: =(SUM(H36:H47)+SUM(H56:H59))*0.8 -> 1840
H22: 합계 | I22: 지상 | J22: =J16+J19 -> 481009.63 | K22: =ROUNDDOWN(J22*0.3025,2) -> 145505.41 | L22: =J22/$J$22 -> 1 | P22: 세대당1대(전용60㎡초과) | Q22: =(SUM(H48:H51)+SUM(H60:H75))*1 -> 2497
I23: 지하 | J23: =J17+J20 -> 317501 | K23: =ROUNDDOWN(J23*0.3025,2) -> 96044.05 | P23: 소 계 | Q23: =SUM(Q21:Q22) -> 4337
I24: 합계 | J24: =J18+J21 -> 798510.63 | K24: =ROUNDDOWN(J24*0.3025,2) -> 241549.46 | O24: 근린생활시설 | P24: 134 | Q24: =(M89+O89)/P24 -> 45.522388 | R24: =ROUNDUP(Q24*S24,0) -> 55 | S24: 1.2
O25: 합 계 | Q25: =Q20+Q24 -> 4745.5224 | R25: =SUM(R18+R24) -> 7250.5
G26: 건축면적 | H26: =J14*0.2842 -> 45584.685 | K26: =ROUNDDOWN(H26*0.3025,2) -> 13789.36 | L26: 50
G27: 건폐율 | H27: =H26/J14 -> 0.2842 | N27: 재건축 소택임대비율 | O27: =H29 -> 2.9988786 | P27: 2.5 | Q27: 2 | R27: =(O27-P27)/Q27 -> 0.2494393 | S27: =R28 -> 40009.19 | T27: =P29+P30+P31 -> 470
G28: 용적률 산정 연면적 | H28: =J22 -> 481009.63 | K28: =ROUNDDOWN(H28*0.3025,2) -> 145505.41 | L28: 법적상한용적률 ( 300% 이하 ) | P28: =J14 -> 160396.5 | Q28: =R27 -> 0.2494393 | R28: =P28*Q28 -> 40009.19
G29: 용 적 율 | H29: =H28/J14 -> 2.9988786 | O29: =G45 -> 49 | P29: =H42 -> 190 | Q29: =N42 -> 71.05 | R29: =P29*Q29 -> 13499.5 | S29: =R29+R30+R31 -> 40074.1 | V29: =S29-S27 -> 64.91
G30: 세 대 수 | H30: =H78 -> 4797 | O30: =G47 -> 59 | P30: =H46 -> 190 | Q30: =N46 -> 85.35 | R30: =P30*Q30 -> 16216.5
G31: 주차대수 | H31: =R25 -> 7250.5 | L31: =$R$18/$H$78 -> 1.5 | O31: =G51 -> 84 | P31: =H50 -> 90 | Q31: =N50 -> 115.09 | R31: =P31*Q31 -> 10358.1
G33: ■ 아파트 분양면적표
G34: 구 분 | H34: 세대수 | I34: 세대비 | J34: 주거전용 | K34: 주 거 공 용 면 적 | N34: 공급면적 | O34: 기타공용면적 | R34: 소 계 | S34: 계약면적 | T34: 비 고
K35: 벽체공용 | L35: 코어공용 | M35: 소 계 | O35: 기계,전기실 | P35: 부대복리시설 | Q35: 지하주차장
E36: =ROUNDUP(H78*0.05,0) -> 240 | F36: =H36/#REF! -> #REF! | G36: =ROUNDDOWN(N37,0) -> 17 | I36: =H36/$H$78 -> 0 | J36: =J54 -> 39.96 | K36: =K54 -> 3.65 | L36: =L54 -> 14.8 | M36: =K36+L36 -> 18.45 | N36: =J36+M36 -> 58.41 | O36: =$O$78/$J$78*J36 -> 0.12075282 | P36: =$P$78/$J$78*J36 -> 1.1304764 | Q36: =$Q$78/$J$78*J36 -> 34.755076 | R36: =O36+P36+Q36 -> 36.006305 | S36: =N36+R36 -> 94.416305 | T36: 의무임대
G37: 39 | J37: =ROUNDDOWN(J36*0.3025,2) -> 12.08 | K37: =ROUNDDOWN(K36*0.3025,2) -> 1.1 | L37: =ROUNDDOWN(L36*0.3025,2) -> 4.47 | M37: =ROUNDDOWN(M36*0.3025,2) -> 5.58 | N37: =ROUNDDOWN(N36*0.3025,2) -> 17.66 | O37: =ROUNDDOWN(O36*0.3025,2) -> 0.03 | P37: =ROUNDDOWN(P36*0.3025,2) -> 0.34 | Q37: =ROUNDDOWN(Q36*0.3025,2) -> 10.51 | ... S37: =ROUNDDOWN(S36*0.3025,2) -> 28.56
F38: =H38/#REF! -> #REF! | G38: =ROUNDDOWN(N39,0) -> 21 | I38: =H38/$H$78 -> 0 | J38: =J56 -> 49.95 | K38: =K56 -> 4.5 | L38: =L56 -> 16.6 | M38: =K38+L38 -> 21.1 | N38: =M38+J38 -> 71.05 | O38: =$O$78/$J$78*J38 -> 0.15094102 | P38: =$P$78/$J$78*J38 -> 1.4130955 | Q38: =$Q$78/$J$78*J38 -> 43.443845 | R38: =O38+P38+Q38 -> 45.007882 | S38: =N38+R38 -> 116.05788
G39: =ROUNDDOWN(J38,0) -> 49 | J39: =ROUNDDOWN(J38*0.3025,2) -> 15.1 | K39: =ROUNDDOWN(K38*0.3025,2) -> 1.36 | L39: =ROUNDDOWN(L38*0.3025,2) -> 5.02 | M39: =ROUNDDOWN(M38*0.3025,2) -> 6.38 | N39: =ROUNDDOWN(N38*0.3025,2) -> 21.49 | O39: =ROUNDDOWN(O38*0.3025,2) -> 0.04 | P39: =ROUNDDOWN(P38*0.3025,2) -> 0.42 | Q39: =ROUNDDOWN(Q38*0.3025,2) -> 13.14 | ... S39: =ROUNDDOWN(S38*0.3025,2) -> 35.1
F40: =H40/#REF! -> #REF! | G40: =ROUNDDOWN(N41,0) -> 25 | I40: =H40/$H$78 -> 0 | J40: =J58 -> 59.95 | K40: =K58 -> 5.8 | L40: =L58 -> 19.6 | M40: =K40+L40 -> 25.4 | N40: =M40+J40 -> 85.35 | O40: =$O$78/$J$78*J40 -> 0.18115945 | P40: =$P$78/$J$78*J40 -> 1.6959975 | Q40: =$Q$78/$J$78*J40 -> 52.141312 | R40: =O40+P40+Q40 -> 54.018469 | S40: =N40+R40 -> 139.36847
G41: =ROUNDDOWN(J40,0) -> 59 | J41: =ROUNDDOWN(J40*0.3025,2) -> 18.13 | K41: =ROUNDDOWN(K40*0.3025,2) -> 1.75 | L41: =ROUNDDOWN(L40*0.3025,2) -> 5.92 | M41: =ROUNDDOWN(M40*0.3025,2) -> 7.68 | N41: =ROUNDDOWN(N40*0.3025,2) -> 25.81 | O41: =ROUNDDOWN(O40*0.3025,2) -> 0.05 | P41: =ROUNDDOWN(P40*0.3025,2) -> 0.51 | Q41: =ROUNDDOWN(Q40*0.3025,2) -> 15.77 | ... S41: =ROUNDDOWN(S40*0.3025,2) -> 42.15
E42: =H42/$H$52 -> 0.40425532 | G42: =ROUNDDOWN(N43,0) -> 21 | H42: 190 | I42: =H42/$H$78 -> 0.039608088 | J42: =J56 -> 49.95 | K42: =K56 -> 4.5 | L42: =L56 -> 16.6 | M42: =K42+L42 -> 21.1 | N42: =M42+J42 -> 71.05 | O42: =$O$78/$J$78*J42 -> 0.15094102 | P42: =$P$78/$J$78*J42 -> 1.4130955 | Q42: =$Q$78/$J$78*J42 -> 43.443845 | R42: =O42+P42+Q42 -> 45.007882 | S42: =N42+R42 -> 116.05788 | T42: 임대
...

Sheet 설계개요(alt2) (조정)
G2: ■ 설 계 개 요 (4802세대) | N2: ■ 부대복리시설 | S2: 44762
E3: 0.7 | G3: 사업명 | H3: 마포구 성산시영아파트 재건축정비사업 | N3: 구 분 | P3: 법적 설치기준 및 지침기준 | R3: 설치계획 | S3: 비고
E4: =J23/(J14*E3) -> 2.6878451 | G4: 대지위치 | H4: 서울특별시 마포구 성산동 446일대 | N4: 진입도로 | O4: =INDEX($N$103:$R$103,MATCH($H$78,$N$102:$R$102,1)) -> 2000세대 이상 | R4: =INDEX($N$104:$R$104,MATCH($H$78,$N$102:$R$102,1)) -> 20
G5: 지역지구 | H5: 제3종 일반주거지역 | N5: 단지내도로 | O5: 폭 7m 이상 | R5: 7M도로
G6: 건축규모 | H6: 지상 35층 / | I6: =ROUNDUP(E4,0) -> 3 | N6: 관리사무소 | O6: =H78 -> 4802 | Q6: =IF(H78>=50, ROUNDUP((10+(H78-50)*0.05),2), "해당없음") -> 247.6 | R6: 280 | S6: (방재실, MDF포함)
G7: 용도 | H7: 공동주택 및 부대복리시설, 근린생활시설 | N7: 경 비 실 | R7: 280
G8: 대 지 면 적 | H8: 사업면적 | J8: 182618.4 | K8: =ROUNDDOWN(J8*0.3025,2) -> 55242.06 | L8: =J8/$J$8 -> 1 | N8: 경 로 당 | O8: 주민공동시설 총량제 | P8: 1,500세대 이상 (서울시 주택조례) | Q8: 500 | R8: 1100 | S8: *서울시 용적률완화적용
H9: 제외면적 | I9: 도로 | J9: 6830.9 | K9: =ROUNDDOWN(J9*0.3025,2) -> 2066.34 | L9: =J9/$J$8 -> 0.037405322 | N9: 어린이집 | Q9: 725 | R9: 1400 | S9: *서울시 용적률완화적용
C10: 1000세대이상 | D10: 3 | E10: =$H$78*D10 -> 14406 | I10: 유치원 | J10: 1000 | K10: =ROUNDDOWN(J10*0.3025,2) -> 302.5 | L10: =J10/$J$8 -> 0.0054758995 | N10: 작은도서관 | Q10: 298 | R10: 650
I11: 공원 | J11: =(H78*3)+30 -> 14436 | K11: =ROUNDDOWN(J11*0.3025,2) -> 4366.89 | L11: =J11/$J$8 -> 0.079050085 | N11: 다함께돌봄센터 | P11: =IF(H78>=500,"500세대이상 의무설치", "해당없음") -> 500세대이상 의무설치 | Q11: =IF(H78>=500,"66㎡ 이상", "해당없음") -> 66㎡ 이상 | R11: 600
N12: 주민공동시설 | R12: 5500
I13: 소계 | J13: =SUM(J9:J12) -> 22266.9 | K13: =ROUNDDOWN(J13*0.3025,2) -> 6735.73 | L13: =J13/$J$8 -> 0.12193131 | N13: 주민운동시설(옥외) | P13: =IF(H78>=500,"500세대이상 의무설치", "해당없음") -> 500세대이상 의무설치 | R13: 3800
H14: 실사용 대지면적 | J14: =J8-J13 -> 160351.5 | K14: =ROUNDDOWN(J14*0.3025,2) -> 48506.32 | L14: =J14/$J$8 -> 0.87806869 | N14: 어린이놀이터(옥외) | P14: =IF(H78<100,"해당없음",IF(H78<300,"지역여건에 맞게 설치",IF(H78<1000,"200㎡+세대당 1㎡",IF(H78>1000,"500㎡+세대당 0.7㎡")))) -> 500㎡+세대당 0.7㎡ | Q14: =500+(H78*0.7) -> 3861.4 | R14: 3700
C15: 120698 | G15: 연 면 적 | H15: 구 분 | J15: 계 획 | L15: 비 율 | N15: 총량검토 | O15: (500㎡+세대당 x 2㎡) x 1.25이상 설치 | Q15: =500+($H$78*2)*1.25 -> 12505 | R15: =R8+R9+R10+R11+R12+R13+R14 -> 16750 | S15: 총량제 면적 (관리사무소 제외)
C16: 93504.3 | D16: =C16/C15 -> 0.77469635 | H16: 아파트 | I16: 지상 | J16: =N78+R8+R9+R7 -> 479863.6 | K16: =ROUNDDOWN(J16*0.3025,2) -> 145158.73 | L16: =J16/$J$22 -> 0.99255373 | N16: 조경시설 | O16: 대지면적 x 0.15 | Q16: =J14*0.15 -> 24052.725 | R16: =ROUNDUP(Q16,-2)+100 -> 24200 | V16: 주차대당
I17: 지하 | J17: =O78+Q78+R6+R10+R12+R11 -> 296200 | K17: =ROUNDDOWN(J17*0.3025,2) -> 89600.5 | N17: 유치원 | R17: 1000 | S17: *유치원용지 계획 | V17: 40
I18: 소계 | J18: =SUM(J16:J17) -> 776063.6 | K18: =ROUNDDOWN(J18*0.3025,2) -> 234759.23 | N18: 주차대수 | O18: 면적기준 | P18: 85㎡이하 전용/75 | Q18: =ROUNDUP((SUMPRODUCT(H36:H51,J36:J51)+SUMPRODUCT(H56:H63,J56:J63))/75,0) -> 4335 | R18: =H78*S18 -> 7203 | S18: 1.5
H19: 근린생활시설 | I19: 지상 | J19: =M85 -> 3600 | K19: =ROUNDDOWN(J19*0.3025,2) -> 1089 | L19: =J19/$J$22 -> 0.007446269 | P19: 85㎡초과 전용/65 | Q19: =ROUNDUP((SUMPRODUCT(H64:H75,J64:J75))/65,0) -> 475
I20: 지하 | J20: =M87+O89+P89 -> 5500 | K20: =ROUNDDOWN(J20*0.3025,2) -> 1663.75 | P20: 소 계 | Q20: =SUM(Q18:Q19) -> 4810
I21: 소계 | J21: =J19+J20 -> 9100 | K21: =ROUNDDOWN(J21*0.3025,2) -> 2752.75 | O21: 세대기준 | P21: 세대당0.8대(전용60㎡이하) | Q21: =(SUM(H36:H47)+SUM(H56:H59))*0.8 -> 1577.6
H22: 합계 | I22: 지상 | J22: =J16+J19 -> 483463.6 | K22: =ROUNDDOWN(J22*0.3025,2) -> 146247.73 | L22: =J22/$J$22 -> 1 | P22: 세대당1대(전용60㎡초과) | Q22: =(SUM(H48:H51)+SUM(H60:H75))*1 -> 2830
I23: 지하 | J23: =J17+J20 -> 301700 | K23: =ROUNDDOWN(J23*0.3025,2) -> 91264.25 | P23: 소 계 | Q23: =SUM(Q21:Q22) -> 4407.6
I24: 합계 | J24: =J18+J21 -> 785163.6 | K24: =ROUNDDOWN(J24*0.3025,2) -> 237511.98 | O24: 근린생활시설 | P24: 134 | Q24: =(M89+O89)/P24 -> 50 | R24: =ROUNDUP(Q24*S24,0) -> 60 | S24: 1.2
O25: 합 계 | Q25: =Q20+Q24 -> 4860 | R25: =SUM(R18+R24) -> 7263
G26: 건축면적 | H26: =J14*0.2842 -> 45571.896 | K26: =ROUNDDOWN(H26*0.3025,2) -> 13785.49 | L26: 50
G27: 건폐율 | H27: =H26/J14 -> 0.2842 | N27: 재건축 소택임대비율 | O27: =H29 -> 2.9994331 | P27: 2.5 | Q27: 2 | R27: =(O27-P27)/Q27 -> 0.24971656 | S27: =R28 -> 40042.425 | T27: =P29+P30+P31 -> 483
G28: 용적률 산정 연면적 | H28: =J22-R8-R9 -> 480963.6 | K28: =ROUNDDOWN(H28*0.3025,2) -> 145491.48 | L28: 법적상한용적률 ( 300% 이하 ) | P28: =J14 -> 160351.5 | Q28: =R27 -> 0.24971656 | R28: =P28*Q28 -> 40042.425
G29: 용 적 율 | H29: =H28/J14 -> 2.9994331 | O29: =G45 -> 49 | P29: =H42 -> 193 | Q29: =N42 -> 68.25 | R29: =P29*Q29 -> 13172.25 | S29: =R29+R30+R31 -> 40075.75 | V29: =S29-S27 -> 33.325
G30: 세 대 수 | H30: =H78 -> 4802 | O30: =G47 -> 59 | P30: =H46 -> 190 | Q30: =N46 -> 82.15 | R30: =P30*Q30 -> 15608.5
G31: 주차대수 | H31: =R25 -> 7263 | L31: =$R$18/$H$78 -> 1.5 | O31: =G51 -> 84 | P31: =H50 -> 100 | Q31: =N50 -> 112.95 | R31: =P31*Q31 -> 11295
G33: ■ 아파트 분양면적표
G34: 구 분 | H34: 세대수 | I34: 세대비 | J34: 주거전용 | K34: 주 거 공 용 면 적 | N34: 공급면적 | O34: 기타공용면적 | R34: 소 계 | S34: 계약면적 | T34: 비 고
K35: 벽체공용 | L35: 코어공용 | M35: 소 계 | O35: 기계,전기실 | P35: 부대복리시설 | Q35: 지하주차장
E36: =ROUNDUP(H78*0.05,0) -> 241 | F36: =H36/#REF! -> #REF! | G36: =ROUNDDOWN(N37,0) -> 17 | I36: =H36/$H$78 -> 0 | J36: =J54 -> 39.96 | K36: =K54 -> 3.65 | L36: =L54 -> 14.8 | M36: =K36+L36 -> 18.45 | N36: =J36+M36 -> 58.41 | O36: =$O$78/$J$78*J36 -> 0.11787056 | P36: =$P$78/$J$78*J36 -> 1.1012478 | Q36: =$Q$78/$J$78*J36 -> 32.343682 | R36: =O36+P36+Q36 -> 33.5628 | S36: =N36+R36 -> 91.9728 | T36: 의무임대
G37: 39 | J37: =ROUNDDOWN(J36*0.3025,2) -> 12.08 | K37: =ROUNDDOWN(K36*0.3025,2) -> 1.1 | L37: =ROUNDDOWN(L36*0.3025,2) -> 4.47 | M37: =ROUNDDOWN(M36*0.3025,2) -> 5.58 | N37: =ROUNDDOWN(N36*0.3025,2) -> 17.66 | O37: =ROUNDDOWN(O36*0.3025,2) -> 0.03 | P37: =ROUNDDOWN(P36*0.3025,2) -> 0.33 | Q37: =ROUNDDOWN(Q36*0.3025,2) -> 9.78 | ... S37: =ROUNDDOWN(S36*0.3025,2) -> 27.82
F38: =H38/#REF! -> #REF! | G38: =ROUNDDOWN(N39,0) -> 20 | I38: =H38/$H$78 -> 0 | J38: =J56 -> 49.9 | K38: =K56 -> 3.85 | L38: =L56 -> 14.9 | M38: =K38+L38 -> 18.75 | N38: =M38+J38 -> 68.65 | O38: =$O$78/$J$78*J38 -> 0.14719071 | P38: =$P$78/$J$78*J38 -> 1.3751818 | Q38: =$Q$78/$J$78*J38 -> 40.389132 | R38: =O38+P38+Q38 -> 41.911504 | S38: =N38+R38 -> 110.5615
G39: =ROUNDDOWN(J38,0) -> 49 | J39: =ROUNDDOWN(J38*0.3025,2) -> 15.09 | K39: =ROUNDDOWN(K38*0.3025,2) -> 1.16 | L39: =ROUNDDOWN(L38*0.3025,2) -> 4.5 | M39: =ROUNDDOWN(M38*0.3025,2) -> 5.67 | N39: =ROUNDDOWN(N38*0.3025,2) -> 20.76 | O39: =ROUNDDOWN(O38*0.3025,2) -> 0.04 | P39: =ROUNDDOWN(P38*0.3025,2) -> 0.41 | Q39: =ROUNDDOWN(Q38*0.3025,2) -> 12.21 | ... S39: =ROUNDDOWN(S38*0.3025,2) -> 33.44
F40: =H40/#REF! -> #REF! | G40: =ROUNDDOWN(N41,0) -> 24 | I40: =H40/$H$78 -> 0 | J40: =J58 -> 59.95 | K40: =K58 -> 5.8 | L40: =L58 -> 16.4 | M40: =K40+L40 -> 22.2 | N40: =M40+J40 -> 82.15 | O40: =$O$78/$J$78*J40 -> 0.17683534 | P40: =$P$78/$J$78*J40 -> 1.6521473 | Q40: =$Q$78/$J$78*J40 -> 48.523616 | R40: =O40+P40+Q40 -> 50.352599 | S40: =N40+R40 -> 132.5026
G41: =ROUNDDOWN(J40,0) -> 59 | J41: =ROUNDDOWN(J40*0.3025,2) -> 18.13 | K41: =ROUNDDOWN(K40*0.3025,2) -> 1.75 | L41: =ROUNDDOWN(L40*0.3025,2) -> 4.96 | M41: =ROUNDDOWN(M40*0.3025,2) -> 6.71 | N41: =ROUNDDOWN(N40*0.3025,2) -> 24.85 | O41: =ROUNDDOWN(O40*0.3025,2) -> 0.05 | P41: =ROUNDDOWN(P40*0.3025,2) -> 0.49 | Q41: =ROUNDDOWN(Q40*0.3025,2) -> 14.67 | ... S41: =ROUNDDOWN(S40*0.3025,2) -> 40.08
E42: =H42/$H$52 -> 0.39958592 | G42: =ROUNDDOWN(N43,0) -> 20 | H42: 193 | I42: =H42/$H$78 -> 0.040191587 | J42: 49.9 | K42: 3.85 | L42: 14.5 | M42: =K42+L42 -> 18.35 | N42: =M42+J42 -> 68.25 | O42: =$O$78/$J$78*J42 -> 0.14719071 | P42: =$P$78/$J$78*J42 -> 1.3751818 | Q42: =$Q$78/$J$78*J42 -> 40.389132 | R42: =O42+P42+Q42 -> 41.911504 | S42: =N42+R42 -> 110.1615 | T42: 임대 | U42: =J42/N42 -> 0.73113553
...

Sheet 설계개요(통합)
G2: ■ 설 계 개 요 (4802세대) | N2: ■ 부대복리시설 | T2: 7.21 | V2: 44763
E3: 0.7 | G3: 사업명 | H3: 마포구 성산시영아파트 재건축정비사업 | N3: 구 분 | P3: 법적 설치기준 및 지침기준 | R3: 설치계획 | S3: 비고
E4: =J23/(J14*E3) -> 2.6905226 | G4: 대지위치 | H4: 서울특별시 마포구 성산동 446일대 | N4: 진입도로 | O4: =INDEX($N$103:$R$103,MATCH($H$78,$N$102:$R$102,1)) -> 2000세대 이상 | R4: =INDEX($N$104:$R$104,MATCH($H$78,$N$102:$R$102,1)) -> 20
G5: 지역지구 | H5: 제3종 일반주거지역 | N5: 단지내도로 | O5: 폭 7m 이상 | R5: 7M도로
G6: 건축규모 | H6: 지상 35층 / | I6: =ROUNDUP(E4,0) -> 3 | N6: 관리사무소 | O6: =H78 -> 4805 | Q6: =IF(H78>=50, ROUNDUP((10+(H78-50)*0.05),2), "해당없음") -> 247.75 | R6: 280 | S6: (방재실, MDF포함)
G7: 용도 | H7: 공동주택 및 부대복리시설, 근린생활시설 | N7: 경 비 실 | R7: 280
G8: 대 지 면 적 | H8: 사업면적 | J8: 182618.4 | K8: =ROUNDDOWN(J8*0.3025,2) -> 55242.06 | L8: =J8/$J$8 -> 1 | N8: 경 로 당 | O8: 주민공동시설 총량제 | P8: 1,500세대 이상 (서울시 주택조례) | Q8: 500 | R8: 1100 | S8: *서울시 용적률완화적용
H9: 제외면적 | I9: 도로 | J9: 6830.9 | K9: =ROUNDDOWN(J9*0.3025,2) -> 2066.34 | L9: =J9/$J$8 -> 0.037405322 | N9: 어린이집 | Q9: 725 | R9: 1400 | S9: *서울시 용적률완화적용
C10: 1000세대이상 | D10: 3 | E10: =$H$78*D10 -> 14415 | I10: 유치원 | J10: 1000 | K10: =ROUNDDOWN(J10*0.3025,2) -> 302.5 | L10: =J10/$J$8 -> 0.0054758995 | N10: 작은도서관 | Q10: 298 | R10: 650
I11: 공원 | J11: 14500 | K11: =ROUNDDOWN(J11*0.3025,2) -> 4386.25 | L11: =J11/$J$8 -> 0.079400542 | N11: 다함께돌봄센터 | P11: =IF(H78>=500,"500세대이상 의무설치", "해당없음") -> 500세대이상 의무설치 | Q11: =IF(H78>=500,"66㎡ 이상", "해당없음") -> 66㎡ 이상 | R11: 600
N12: 주민공동시설 | R12: 5500
I13: 소계 | J13: =SUM(J9:J12) -> 22330.9 | K13: =ROUNDDOWN(J13*0.3025,2) -> 6755.09 | L13: =J13/$J$8 -> 0.12228176 | N13: 주민운동시설(옥외) | P13: =IF(H78>=500,"500세대이상 의무설치", "해당없음") -> 500세대이상 의무설치 | R13: 3800
H14: 실사용 대지면적 | J14: =J8-J13 -> 160287.5 | K14: =ROUNDDOWN(J14*0.3025,2) -> 48486.96 | L14: =J14/$J$8 -> 0.87771824 | N14: 어린이놀이터(옥외) | P14: =IF(H78<100,"해당없음",IF(H78<300,"지역여건에 맞게 설치",IF(H78<1000,"200㎡+세대당 1㎡",IF(H78>1000,"500㎡+세대당 0.7㎡")))) -> 500㎡+세대당 0.7㎡ | Q14: =500+(H78*0.7) -> 3863.5 | R14: 3700
C15: 120698 | G15: 연 면 적 | H15: 구 분 | J15: 계 획 | L15: 비 율 | N15: 총량검토 | O15: (500㎡+세대당 x 2㎡) x 1.25이상 설치 | Q15: =500+($H$78*2)*1.25 -> 12512.5 | R15: =R8+R9+R10+R11+R12+R13+R14 -> 16750 | S15: 총량제 면적 (관리사무소 제외)
C16: 93504.3 | D16: =C16/C15 -> 0.77469635 | H16: 아파트 | I16: 지상 | J16: =N78+R8+R9+R7 -> 479083.45 | K16: =ROUNDDOWN(J16*0.3025,2) -> 144922.74 | L16: =J16/$J$22 -> 0.9925417 | N16: 조경시설 | O16: 대지면적 x 0.15 | Q16: =J14*0.15 -> 24043.125 | R16: =ROUNDUP(Q16,-2)+100 -> 24200 | V16: 주차대당
I17: 지하 | J17: =O78+Q78+R6+R10+R12+R11 -> 296380 | K17: =ROUNDDOWN(J17*0.3025,2) -> 89654.95 | N17: 유치원 | R17: 1000 | S17: *유치원용지 계획 | V17: 40
I18: 소계 | J18: =SUM(J16:J17) -> 775463.45 | K18: =ROUNDDOWN(J18*0.3025,2) -> 234577.69 | N18: 주차대수 | O18: 면적기준 | P18: 85㎡이하 전용/75 | Q18: =ROUNDUP((SUMPRODUCT(H36:H51,J36:J51)+SUMPRODUCT(H56:H63,J56:J63))/75,0) -> 4307 | R18: =H78*S18 -> 7207.5 | S18: 1.5
H19: 근린생활시설 | I19: 지상 | J19: =M85 -> 3600 | K19: =ROUNDDOWN(J19*0.3025,2) -> 1089 | L19: =J19/$J$22 -> 0.0074583042 | P19: 85㎡초과 전용/65 | Q19: =ROUNDUP((SUMPRODUCT(H64:H75,J64:J75))/65,0) -> 502
I20: 지하 | J20: =M87+O89+P89 -> 5500 | K20: =ROUNDDOWN(J20*0.3025,2) -> 1663.75 | P20: 소 계 | Q20: =SUM(Q18:Q19) -> 4809
I21: 소계 | J21: =J19+J20 -> 9100 | K21: =ROUNDDOWN(J21*0.3025,2) -> 2752.75 | O21: 세대기준 | P21: 세대당0.8대(전용60㎡이하) | Q21: =(SUM(H36:H47)+SUM(H56:H59))*0.8 -> 1662.4
H22: 합계 | I22: 지상 | J22: =J16+J19 -> 482683.45 | K22: =ROUNDDOWN(J22*0.3025,2) -> 146011.74 | L22: =J22/$J$22 -> 1 | P22: 세대당1대(전용60㎡초과) | Q22: =(SUM(H48:H51)+SUM(H60:H75))*1 -> 2727
I23: 지하 | J23: =J17+J20 -> 301880 | K23: =ROUNDDOWN(J23*0.3025,2) -> 91318.7 | P23: 소 계 | Q23: =SUM(Q21:Q22) -> 4389.4
I24: 합계 | J24: =J18+J21 -> 784563.45 | K24: =ROUNDDOWN(J24*0.3025,2) -> 237330.44 | O24: 근린생활시설 | P24: 134 | Q24: =(M89+O89)/P24 -> 50 | R24: =ROUNDUP(Q24*S24,0) -> 60 | S24: 1.2
O25: 합 계 | Q25: =Q20+Q24 -> 4859 | R25: =SUM(R18+R24) -> 7267.5
G26: 건축면적 | H26: =J14*0.2842 -> 45553.708 | K26: =ROUNDDOWN(H26*0.3025,2) -> 13779.99 | L26: 50
G27: 건폐율 | H27: =H26/J14 -> 0.2842 | N27: 재건축 소택임대비율 | O27: =H29 -> 2.9957635 | P27: 2.5 | Q27: 2 | R27: =(O27-P27)/Q27 -> 0.24788177 | S27: =R28 -> 39732.35 | T27: =P29+P30+P31 -> 510
G28: 용적률 산정 연면적 | H28: =J22-R8-R9 -> 480183.45 | K28: =ROUNDDOWN(H28*0.3025,2) -> 145255.49 | L28: 법적상한용적률 ( 300% 이하 ) | P28: =J14 -> 160287.5 | Q28: =R27 -> 0.24788177 | R28: =P28*Q28 -> 39732.35
G29: 용 적 율 | H29: =H28/J14 -> 2.9957635 | O29: =G45 -> 49 | P29: =H42 -> 230 | Q29: =N42 -> 68.65 | R29: =P29*Q29 -> 15789.5 | S29: =R29+R30+R31 -> 40331.5 | V29: =S29-S27 -> 599.15
G30: 세 대 수 | H30: =H78 -> 4805 | O30: =G47 -> 59 | P30: =H46 -> 230 | Q30: =N46 -> 82.15 | R30: =P30*Q30 -> 18894.5
G31: 주차대수 | H31: =R25 -> 7267.5 | L31: =$R$18/$H$78 -> 1.5 | O31: =G51 -> 84 | P31: =H50 -> 50 | Q31: =N50 -> 112.95 | R31: =P31*Q31 -> 5647.5
G33: ■ 아파트 분양면적표
G34: 구 분 | H34: 세대수 | I34: 세대비 | J34: 주거전용 | K34: 주 거 공 용 면 적 | N34: 공급면적 | O34: 기타공용면적 | R34: 소 계 | S34: 계약면적 | T34: 비 고
K35: 벽체공용 | L35: 코어공용 | M35: 소 계 | O35: 기계,전기실 | P35: 부대복리시설 | Q35: 지하주차장
E36: =ROUNDUP(H78*0.05,0) -> 241 | F36: =H36/#REF! -> #REF! | G36: =ROUNDDOWN(N37,0) -> 17 | I36: =H36/$H$78 -> 0 | J36: =J54 -> 39.96 | K36: =K54 -> 3.65 | L36: =L54 -> 14.8 | M36: =K36+L36 -> 18.45 | N36: =J36+M36 -> 58.41 | O36: =$O$78/$J$78*J36 -> 0.11800339 | P36: =$P$78/$J$78*J36 -> 1.1024888 | Q36: =$Q$78/$J$78*J36 -> 32.40036 | R36: =O36+P36+Q36 -> 33.620852 | S36: =N36+R36 -> 92.030852 | T36: 의무임대
G37: 39 | J37: =ROUNDDOWN(J36*0.3025,2) -> 12.08 | K37: =ROUNDDOWN(K36*0.3025,2) -> 1.1 | L37: =ROUNDDOWN(L36*0.3025,2) -> 4.47 | M37: =ROUNDDOWN(M36*0.3025,2) -> 5.58 | N37: =ROUNDDOWN(N36*0.3025,2) -> 17.66 | O37: =ROUNDDOWN(O36*0.3025,2) -> 0.03 | P37: =ROUNDDOWN(P36*0.3025,2) -> 0.33 | Q37: =ROUNDDOWN(Q36*0.3025,2) -> 9.8 | ... S37: =ROUNDDOWN(S36*0.3025,2) -> 27.83
F38: =H38/#REF! -> #REF! | G38: =ROUNDDOWN(N39,0) -> 20 | I38: =H38/$H$78 -> 0 | J38: =J56 -> 49.9 | K38: =K56 -> 3.85 | L38: =L56 -> 14.9 | M38: =K38+L38 -> 18.75 | N38: =M38+J38 -> 68.65 | O38: =$O$78/$J$78*J38 -> 0.14735659 | P38: =$P$78/$J$78*J38 -> 1.3767316 | Q38: =$Q$78/$J$78*J38 -> 40.459909 | R38: =O38+P38+Q38 -> 41.983997 | S38: =N38+R38 -> 110.634
G39: =ROUNDDOWN(J38,0) -> 49 | J39: =ROUNDDOWN(J38*0.3025,2) -> 15.09 | K39: =ROUNDDOWN(K38*0.3025,2) -> 1.16 | L39: =ROUNDDOWN(L38*0.3025,2) -> 4.5 | M39: =ROUNDDOWN(M38*0.3025,2) -> 5.67 | N39: =ROUNDDOWN(N38*0.3025,2) -> 20.76 | O39: =ROUNDDOWN(O38*0.3025,2) -> 0.04 | P39: =ROUNDDOWN(P38*0.3025,2) -> 0.41 | Q39: =ROUNDDOWN(Q38*0.3025,2) -> 12.23 | ... S39: =ROUNDDOWN(S38*0.3025,2) -> 33.46
F40: =H40/#REF! -> #REF! | G40: =ROUNDDOWN(N41,0) -> 24 | I40: =H40/$H$78 -> 0 | J40: =J58 -> 59.95 | K40: =K58 -> 5.8 | L40: =L58 -> 16.4 | M40: =K40+L40 -> 22.2 | N40: =M40+J40 -> 82.15 | O40: =$O$78/$J$78*J40 -> 0.17703462 | P40: =$P$78/$J$78*J40 -> 1.6540091 | Q40: =$Q$78/$J$78*J40 -> 48.608648 | R40: =O40+P40+Q40 -> 50.439692 | S40: =N40+R40 -> 132.58969
G41: =ROUNDDOWN(J40,0) -> 59 | J41: =ROUNDDOWN(J40*0.3025,2) -> 18.13 | K41: =ROUNDDOWN(K40*0.3025,2) -> 1.75 | L41: =ROUNDDOWN(L40*0.3025,2) -> 4.96 | M41: =ROUNDDOWN(M40*0.3025,2) -> 6.71 | N41: =ROUNDDOWN(N40*0.3025,2) -> 24.85 | O41: =ROUNDDOWN(O40*0.3025,2) -> 0.05 | P41: =ROUNDDOWN(P40*0.3025,2) -> 0.5 | Q41: =ROUNDDOWN(Q40*0.3025,2) -> 14.7 | ... S41: =ROUNDDOWN(S40*0.3025,2) -> 40.1
E42: =H42/$H$52 -> 0.45098039 | G42: =ROUNDDOWN(N43,0) -> 20 | H42: 230 | I42: =H42/$H$78 -> 0.047866805 | J42: 49.9 | K42: 3.85 | L42: 14.9 | M42: =K42+L42 -> 18.75 | N42: =M42+J42 -> 68.65 | O42: =$O$78/$J$78*J42 -> 0.14735659 | P42: =$P$78/$J$78*J42 -> 1.3767316 | Q42: =$Q$78/$J$78*J42 -> 40.459909 | R42: =O42+P42+Q42 -> 41.983997 | S42: =N42+R42 -> 110.634 | T42: 임대 | U42: =J42/N42 -> 0.72687546
...

Sheet 설계개요(통합개요)
G2: ■ 설 계 개 요 (통합개요) | N2: ■ 부대복리시설 | T2: 7.21 | V2: 44763
E3: 0.7 | G3: 사업명 | H3: 마포구 성산시영아파트 재건축정비사업 | N3: 구 분 | P3: 법적 설치기준 및 지침기준 | R3: 설치계획 | S3: 비고
E4: =J23/(J14*E3) -> #VALUE! | G4: 대지위치 | H4: 서울특별시 마포구 성산동 446일대 | N4: 진입도로 | O4: =INDEX($N$103:$R$103,MATCH($H$78,$N$102:$R$102,1)) -> #VALUE! | R4: =INDEX($N$104:$R$104,MATCH($H$78,$N$102:$R$102,1)) -> #VALUE!
G5: 지역지구 | H5: 제3종 일반주거지역 | N5: 단지내도로 | O5: 폭 7m 이상 | R5: 7M도로
G6: 건축규모 | H6: 지상 35층 / | I6: =ROUNDUP(E4,0) -> #VALUE! | N6: 관리사무소 | O6: =H78 -> #VALUE! | Q6: =IF(H78>=50, ROUNDUP((10+(H78-50)*0.05),2), "해당없음") -> #VALUE! | R6: ='설계개요(1단지)'!R6+'설계개요(2)'!R6 -> 280 | S6: (방재실, MDF포함)
G7: 용도 | H7: 공동주택 및 부대복리시설, 근린생활시설 | N7: 경 비 실 | R7: ='설계개요(1단지)'!R7+'설계개요(2)'!R7 -> 230
G8: 대 지 면 적 | H8: 사업면적 | J8: 182618.4 | K8: =ROUNDDOWN(J8*0.3025,2) -> 55242.06 | L8: =J8/$J$8 -> 1 | N8: 경 로 당 | O8: 주민공동시설 총량제 | P8: 1,500세대 이상 (서울시 주택조례) | Q8: 500 | R8: ='설계개요(1단지)'!R8+'설계개요(2)'!R8 -> 1320 | S8: *서울시 용적률완화적용
H9: 제외면적 | I9: 도로 | J9: 6830.9 | K9: =ROUNDDOWN(J9*0.3025,2) -> 2066.34 | L9: =J9/$J$8 -> 0.037405322 | N9: 어린이집 | Q9: 725 | R9: ='설계개요(1단지)'!R9+'설계개요(2)'!R9 -> 1700 | S9: *서울시 용적률완화적용
C10: 1000세대이상 | D10: 3 | E10: =$H$78*D10 -> #VALUE! | I10: 유치원 | J10: 1000 | K10: =ROUNDDOWN(J10*0.3025,2) -> 302.5 | L10: =J10/$J$8 -> 0.0054758995 | N10: 작은도서관 | Q10: 298 | R10: ='설계개요(1단지)'!R10+'설계개요(2)'!R10 -> 1150
I11: 공원 | J11: 14500 | K11: =ROUNDDOWN(J11*0.3025,2) -> 4386.25 | L11: =J11/$J$8 -> 0.079400542 | N11: 다함께돌봄센터 | P11: =IF(H78>=500,"500세대이상 의무설치", "해당없음") -> #VALUE! | Q11: =IF(H78>=500,"66㎡ 이상", "해당없음") -> #VALUE! | R11: ='설계개요(1단지)'!R11+'설계개요(2)'!R11 -> 600
N12: 주민공동시설 | R12: ='설계개요(1단지)'!R12+'설계개요(2)'!R12 -> 9545
I13: 소계 | J13: =SUM(J9:J12) -> 22330.9 | K13: =ROUNDDOWN(J13*0.3025,2) -> 6755.09 | L13: =J13/$J$8 -> 0.12228176 | N13: 주민운동시설(옥외) | P13: =IF(H78>=500,"500세대이상 의무설치", "해당없음") -> #VALUE! | R13: ='설계개요(1단지)'!R13+'설계개요(2)'!R13 -> 1800
H14: 실사용 대지면적 | J14: =J8-J13 -> 160287.5 | K14: =ROUNDDOWN(J14*0.3025,2) -> 48486.96 | L14: =J14/$J$8 -> 0.87771824 | N14: 어린이놀이터(옥외) | P14: =IF(H78<100,"해당없음",IF(H78<300,"지역여건에 맞게 설치",IF(H78<1000,"200㎡+세대당 1㎡",IF(H78>1000,"500㎡+세대당 0.7㎡")))) -> #VALUE! | Q14: =500+(H78*0.7) -> #VALUE! | R14: ='설계개요(1단지)'!R14+'설계개요(2)'!R14 -> 3900
C15: 120698 | G15: 연 면 적 | H15: 구 분 | J15: 계 획 | L15: 비 율 | N15: 총량검토 | O15: (500㎡+세대당 x 2㎡) x 1.25이상 설치 | Q15: =500+($H$78*2)*1.25 -> #VALUE! | R15: =R8+R9+R10+R11+R12+R13+R14 -> 20015 | S15: 총량제 면적 (관리사무소 제외)
C16: 93504.3 | D16: =C16/C15 -> 0.77469635 | H16: 아파트 | I16: 지상 | J16: =N78+R8+R9+R7 -> #VALUE! | K16: =ROUNDDOWN(J16*0.3025,2) -> #VALUE! | L16: =J16/$J$22 -> #VALUE! | N16: 조경시설 | O16: 대지면적 x 0.15 | Q16: =J14*0.15 -> 24043.125 | R16: =ROUNDUP(Q16,-2)+100 -> 24200 | V16: 주차대당
I17: 지하 | J17: =O78+Q78+R6+R10+R12+R11 -> #VALUE! | K17: =ROUNDDOWN(J17*0.3025,2) -> #VALUE! | N17: 유치원 | R17: 1000 | S17: *유치원용지 계획 | V17: 40
I18: 소계 | J18: =SUM(J16:J17) -> #VALUE! | K18: =ROUNDDOWN(J18*0.3025,2) -> #VALUE! | N18: 주차대수 | O18: 면적기준 | P18: 85㎡이하 전용/75 | Q18: =ROUNDUP((SUMPRODUCT(H36:H51,J36:J51)+SUMPRODUCT(H56:H63,J56:J63))/75,0) -> #VALUE! | R18: =H78*S18 -> #VALUE! | S18: 1.5
H19: 근린생활시설 | I19: 지상 | J19: =M85 -> 4320 | K19: =ROUNDDOWN(J19*0.3025,2) -> 1306.8 | L19: =J19/$J$22 -> #VALUE! | P19: 85㎡초과 전용/65 | Q19: =ROUNDUP((SUMPRODUCT(H64:H75,J64:J75))/65,0) -> #VALUE! | W19: ='설계개요(1단지)'!J17+'설계개요(2)'!J16 -> 322368.47
I20: 지하 | J20: =M87+O89+P89 -> 6200 | K20: =ROUNDDOWN(J20*0.3025,2) -> 1875.5 | P20: 소 계 | Q20: =SUM(Q18:Q19) -> #VALUE! | W20: ='설계개요(1단지)'!J18+'설계개요(2)'!J17 -> 234525
I21: 소계 | J21: =J19+J20 -> 10520 | K21: =ROUNDDOWN(J21*0.3025,2) -> 3182.3 | O21: 세대기준 | P21: 세대당0.8대(전용60㎡이하) | Q21: =(SUM(H36:H47)+SUM(H56:H59))*0.8 -> #VALUE! | W21: =W19+W20 -> 556893.47
H22: 합계 | I22: 지상 | J22: =J16+J19 -> #VALUE! | K22: =ROUNDDOWN(J22*0.3025,2) -> #VALUE! | L22: =J22/$J$22 -> #VALUE! | P22: 세대당1대(전용60㎡초과) | Q22: =(SUM(H48:H51)+SUM(H60:H75))*1 -> #VALUE! | W22: ='설계개요(1단지)'!J20+'설계개요(2)'!J19 -> 4320
I23: 지하 | J23: =J17+J20 -> #VALUE! | K23: =ROUNDDOWN(J23*0.3025,2) -> #VALUE! | P23: 소 계 | Q23: =SUM(Q21:Q22) -> #VALUE! | W23: ='설계개요(1단지)'!J21+'설계개요(2)'!J20 -> 6200
I24: 합계 | J24: =J18+J21 -> #VALUE! | K24: =ROUNDDOWN(J24*0.3025,2) -> #VALUE! | O24: 근린생활시설 | P24: 134 | Q24: =(M89+O89)/P24 -> 57.61194 | R24: =ROUNDUP(Q24*S24,0) -> 70 | S24: 1.2 | W24: =W22+W23 -> 10520
O25: 합 계 | Q25: =Q20+Q24 -> #VALUE! | R25: =SUM(R18+R24) -> #VALUE! | W25: ='설계개요(1단지)'!J26+'설계개요(2)'!J22 -> 326688.47
G26: 건축면적 | H26: ='설계개요(1단지)'!H30:J30+'설계개요(2)'!H26:J26 -> 20531.45 | K26: =ROUNDDOWN(H26*0.3025,2) -> 6210.76 | L26: 50 | W26: ='설계개요(1단지)'!J27+'설계개요(2)'!J23 -> 240725
G27: 건폐율 | H27: =H26/J14 -> 0.1280914 | N27: 재건축 소택임대비율 | O27: =H29 -> #VALUE! | P27: 2.5 | Q27: 2 | R27: =(O27-P27)/Q27 -> #VALUE! | S27: =R28 -> #VALUE! | T27: =P29+P30+P31 -> #VALUE! | W27: =W25+W26 -> 567413.47
G28: 용적률 산정 연면적 | H28: =J22-R8-R9 -> #VALUE! | K28: =ROUNDDOWN(H28*0.3025,2) -> #VALUE! | L28: 법적상한용적률 ( 300% 이하 ) | P28: =J14 -> 160287.5 | Q28: =R27 -> #VALUE! | R28: =P28*Q28 -> #VALUE!
G29: 용 적 율 | H29: =H28/J14 -> #VALUE! | O29: =G45 -> 49 | P29: =H42 -> #VALUE! | Q29: =N42 -> 67.7 | R29: =P29*Q29 -> #VALUE! | S29: =R29+R30+R31 -> #VALUE! | V29: =S29-S27 -> #VALUE!
G30: 세 대 수 | H30: =H78 -> #VALUE! | O30: =G47 -> 59 | P30: =H46 -> #VALUE! | Q30: =N46 -> 82.65 | R30: =P30*Q30 -> #VALUE!
G31: 주차대수 | H31: =R25 -> #VALUE! | L31: =$R$18/$H$78 -> #VALUE! | O31: =G51 -> 84 | P31: =H50 -> #VALUE! | Q31: =N50 -> 112.95 | R31: =P31*Q31 -> #VALUE!
G33: ■ 아파트 분양면적표
G34: 구 분 | H34: 세대수 | I34: 세대비 | J34: 주거전용 | K34: 주 거 공 용 면 적 | N34: 공급면적 | O34: 기타공용면적 | R34: 소 계 | S34: 계약면적 | T34: 비 고
K35: 벽체공용 | L35: 코어공용 | M35: 소 계 | O35: 기계,전기실 | P35: 부대복리시설 | Q35: 지하주차장
E36: =ROUNDUP(H78*0.05,0) -> #VALUE! | F36: =H36/#REF! -> #REF! | G36: =ROUNDDOWN(N37,0) -> 17 | I36: =H36/$H$78 -> #VALUE! | J36: =J54 -> 39.96 | K36: =K54 -> 3.65 | L36: =L54 -> 14.8 | M36: =K36+L36 -> 18.45 | N36: =J36+M36 -> 58.41 | O36: =$O$78/$J$78*J36 -> #VALUE! | P36: =$P$78/$J$78*J36 -> #VALUE! | Q36: =$Q$78/$J$78*J36 -> #VALUE! | R36: =O36+P36+Q36 -> #VALUE! | S36: =N36+R36 -> #VALUE! | T36: 의무임대
G37: 39 | J37: =ROUNDDOWN(J36*0.3025,2) -> 12.08 | K37: =ROUNDDOWN(K36*0.3025,2) -> 1.1 | L37: =ROUNDDOWN(L36*0.3025,2) -> 4.47 | M37: =ROUNDDOWN(M36*0.3025,2) -> 5.58 | N37: =ROUNDDOWN(N36*0.3025,2) -> 17.66 | O37: =ROUNDDOWN(O36*0.3025,2) -> #VALUE! | P37: =ROUNDDOWN(P36*0.3025,2) -> #VALUE! | Q37: =ROUNDDOWN(Q36*0.3025,2) -> #VALUE! | ... S37: =ROUNDDOWN(S36*0.3025,2) -> #VALUE!
F38: =H38/#REF! -> #REF! | G38: =ROUNDDOWN(N39,0) -> 20 | I38: =H38/$H$78 -> #VALUE! | J38: =J56 -> 49.8 | K38: =K56 -> 3.7 | L38: =L56 -> 14.2 | M38: =K38+L38 -> 17.9 | N38: =M38+J38 -> 67.7 | O38: =$O$78/$J$78*J38 -> #VALUE! | P38: =$P$78/$J$78*J38 -> #VALUE! | Q38: =$Q$78/$J$78*J38 -> #VALUE! | R38: =O38+P38+Q38 -> #VALUE! | S38: =N38+R38 -> #VALUE!
G39: =ROUNDDOWN(J38,0) -> 49 | J39: =ROUNDDOWN(J38*0.3025,2) -> 15.06 | K39: =ROUNDDOWN(K38*0.3025,2) -> 1.11 | L39: =ROUNDDOWN(L38*0.3025,2) -> 4.29 | M39: =ROUNDDOWN(M38*0.3025,2) -> 5.41 | N39: =ROUNDDOWN(N38*0.3025,2) -> 20.47 | O39: =ROUNDDOWN(O38*0.3025,2) -> #VALUE! | P39: =ROUNDDOWN(P38*0.3025,2) -> #VALUE! | Q39: =ROUNDDOWN(Q38*0.3025,2) -> #VALUE! | ... S39: =ROUNDDOWN(S38*0.3025,2) -> #VALUE!
F40: =H40/#REF! -> #REF! | G40: =ROUNDDOWN(N41,0) -> 25 | I40: =H40/$H$78 -> #VALUE! | J40: =J58 -> 59.95 | K40: =K58 -> 6.2 | L40: =L58 -> 16.5 | M40: =K40+L40 -> 22.7 | N40: =M40+J40 -> 82.65 | O40: =$O$78/$J$78*J40 -> #VALUE! | P40: =$P$78/$J$78*J40 -> #VALUE! | Q40: =$Q$78/$J$78*J40 -> #VALUE! | R40: =O40+P40+Q40 -> #VALUE! | S40: =N40+R40 -> #VALUE!
