Workbook

Sheet 개요(전체)_발송
B2: 목동10단지 재건축사업 개요(전체 획지1+획지2)
B3: ■설계개요 | L3: ■부대시설 및 복리시설
B5: 사 업 명 | E5: 목동 10단지 재건축사업 | L5: 구분 | N5: 법적기준 및 설치기준 | R5: 계획 | S5: 비고
B6: 대 지 위 치 | E6: 서울시 양천구 신정동 310번지일대 | L6: 진입도로 | N6: 20m이상(1000세대이상) | Q6: 20m 도로 | R6: 15, 25m도로
B7: 지 역 지 구 | E7: 제1종/제3종일반주거지역, 지구단위계획구역 | L7: 단지내도로 | N7: 7m이상 도로(7m이상 도로 1.5m인도 설치) | Q7: 7m 도로 | R7: 10m도로
B8: 용 도 | E8: 공동주택, 부대시설, 근린생활시설 | L8: 관리사무소 | N8: 50세대 이상, 10m²+(세대수-50) X 0.05m² | Q8: ='1획지'!Q8+'2획지'!Q8 -> 219.05 | R8: ='1획지'!R8+'2획지'!R8 -> 574.71 | S8: MDF/방재실포함
B9: 도 로 현 황 | E9: 북,동,서측 15m도로, 남측 25m, 단지통과 15m도로 | L9: 유치원 | N9: 2,000세대 이상 | Q9: - | S9: 현시설이동
B10: 사업부지면적 | E10: 194686.2 | L10: 주민공동시설 | N10: 1획지/2획지 산정합산 | Q10: ='1획지'!Q10+'2획지'!Q10 -> 11339.375 | R10: ='1획지'!R10+'2획지'!R10 -> 18771.267 | T10: =R10/C65 -> 4.5996733 | V10: 돌봄시설
B11: 기반시설 | C11: 근린공원, 녹지 | E11: =9510+2645.9 -> 12155.9 | G11: =E11+E12 -> 29314.2 | T11: =T10*0.3025 -> 1.3914012 | V11: 의무면적
C12: 도로, 유치원, 사회복지시설, 하수도 | E12: =11813.7+730.7+718.3+3895.6 -> 17158.3 | V12: =Q10*0.2 -> 2267.875 | W12: ='1획지'!R17+'1획지'!R18+'2획지'!R17+'2획지'!R18 -> 1802.4195 | Z12: 조성면적
B13: 공동주택부지면적 | E13: =E10-E11-E12 -> 165372 | G13: =E13*0.3025 -> 50025.03 | L13: 1 | M13: 경로당 | N13: 1획지/2획지 산정합산 | Q13: ='1획지'!Q13+'2획지'!Q13 -> 1307.4 | R13: ='1획지'!R13+'2획지'!R13 -> 1506.6672 | T13: =R13+R8+R15+R17+R18+R19+R20+R21+R24 -> 12983.087 | V13: 법정의무면적 | X13: 계획면적 | Z13: 의무면적제외면적
B14: 건 축 면 적 | E14: ='1획지'!E14+'2획지'!E14 -> 36430.868 | L14: 2 | M14: 어린이놀이터 | N14: 1획지/2획지 산정합산 | Q14: ='1획지'!Q14+'2획지'!Q14 -> 3802.4 | R14: ='1획지'!R14+'2획지'!R14 -> 4067.89 | T14: =T13/C65 -> 3.1813494 | V14: 1획지 | W14: 2획지 | X14: 1획지 | Y14: 2획지 | Z14: 1획지 | AA14: 2획지
B15: 건 폐 율 | E15: =E14/E13 -> 0.22029647 | L15: 3 | M15: 어린이집 | N15: 1획지/2획지 산정합산 | Q15: ='1획지'!Q15+'2획지'!Q15 -> 1307.4 | R15: ='1획지'!R15+'2획지'!R15 -> 1566.12 | U15: 어린이집 | V15: ='1획지'!Q15 -> 330 | W15: ='2획지'!Q15 -> 977.4 | X15: ='1획지'!R15 -> 378.12 | Y15: ='2획지'!R15 -> 1188 | Z15: =X15-V15 -> 48.12 | AA15: =Y15-W15 -> 210.6
B16: 연면적 | C16: 지상 연면적 | E16: =J65+R13+R8+R15+R17+R20+R24+R18+R22+R19 -> 495919.59 | G16: =E16*0.3025 -> 150015.68 | L16: 4 | M16: 주민운동시설 | N16: 1획지/2획지 산정합산 | R16: ='1획지'!R16+'2획지'!R16 -> 2400 | U16: 실내어린이놀이터 | Y16: ='2획지'!U20 -> 978.17 | AA16: =Y16-W16 -> 978.17
C17: 지하 연면적 | E17: =R21+N65+P65+R23 -> 362607.25 | G17: =E17*0.3025 -> 109688.69 | L17: 5 | M17: 작은도서관 | N17: 1획지/2획지 산정합산 | Q17: ='1획지'!Q17+'2획지'!Q17 -> 582.2 | R17: ='1획지'!R17+'2획지'!R17 -> 845.56 | U17: 작은도서관 | V17: ='1획지'!Q17 -> 158 | W17: ='2획지'!Q17 -> 424.2 | X17: ='1획지'!R17 -> 214.88 | Y17: ='2획지'!R17 -> 630.68 | Z17: =X17-V17 -> 56.88 | AA17: =Y17-W17 -> 206.48
C18: 전체 연면적 | E18: =E16+E17 -> 858526.84 | G18: =E18*0.3025 -> 259704.37 | L18: 6 | M18: 다함께돌봄센터 | N18: 1획지/2획지 산정합산 | Q18: ='1획지'!Q18+'2획지'!Q18 -> 132 | R18: ='1획지'!R18+'2획지'!R18 -> 956.8595 | U18: 다함께돌봄센터 | V18: ='1획지'!Q18 -> 66 | W18: ='2획지'!Q18 -> 66 | X18: ='1획지'!R18 -> 214.88 | Y18: ='2획지'!R18 -> 741.9795 | Z18: =X18-V18 -> 148.88 | AA18: =Y18-W18 -> 675.9795
B19: 용적률 산정연면적 | E19: =E16 -> 495919.59 | L19: 7 | M19: 우리동네키움센터 | N19: 1획지/2획지 산정합산 | R19: ='1획지'!R19+'2획지'!R19 -> 450 | U19: 우리동네키움센터 | X19: ='1획지'!R19 -> 0 | Y19: ='2획지'!R19 -> 450 | Z19: =X19-V19 -> 0 | AA19: =Y19-W19 -> 450
B20: 용 적 률 | E20: =E19/E13 -> 2.9988123 | I20: 법정 : 300.00% | L20: 8 | M20: 주민공동시설 | N20: 주민커뮤니티시설 | R20: ='2획지'!R20 -> 978.17 | U20: 소계 | V20: =SUM(V15:V19) -> 554 | W20: =SUM(W15:W19) -> 1467.6 | X20: =SUM(X15:X19) -> 807.88 | Y20: =SUM(Y15:Y19) -> 3988.8295 | Z20: =SUM(Z15:Z19) -> 253.88 | AA20: =SUM(AA15:AA19) -> 2521.2295
B21: 건 축 규 모 | E21: 지하3층,지상37층 | N21: 주민운동시설 | R21: ='1획지'!R21+'2획지'!R21 -> 6000 | S21: 지하 | U21: 총합(A) | W21: =V20+W20 -> 2021.6 | Y21: =X20+Y20 -> 4796.7095 | AA21: =Z20+AA20 -> 2775.1095
B22: 건 물 높 이 | L22: 근린생활시설 | Q22: 지상 | R22: ='1획지'!R22+'2획지'!R22 -> 3785.84 | S22: 상가
C23: 용도 | E23: 아파트 | G23: 근린생활시설 | I23: 합계 | J23: 비율 | Q23: 지하 | R23: ='1획지'!R23+'2획지'!R23 -> 1809.3992 | S23: 기전기실+주차 | U23: 인센티브 | V23: =210%*(AA21/Q10)*0.1 -> 0.051393749
B24: 주차대수 | C24: 산출근거 | E24: 60이하 세대당 0.8대 | F24: =(C47+C54+C44)*0.8 -> 971.2 | G24: 시설면적 134m²당 1대 | L24: 경비실 | N24: 5개소 | R24: ='1획지'!R24+'2획지'!R24 -> 105
E25: 85이하 75m² 당 1대 | F25: =SUMPRODUCT(C55:C58,F55:F58)/75+C48*F48/75+C45*F45/75+C49*F49/75 -> 1525.7765 | L25: 국기게양대 | N25: 세대당 1개소 설치 | R25: 설치 | U25: 경로당 | V25: ='1획지'!Q13 -> 330 | W25: ='2획지'!Q13 -> 977.4 | X25: ='1획지'!R13 -> 448.26 | Y25: ='2획지'!R13 -> 1058.4072 | Z25: =X25-V25 -> 118.26 | AA25: =Y25-W25 -> 81.0072
E26: 85초과 65m² 당 1대 | F26: =SUMPRODUCT(C59:C63,F59:F63)/65 -> 2661.4048 | L26: 안내표지판 | N26: 300세대 이상, 안내표지판등 설치 | R26: 설치 | U26: 어린이놀이터 | V26: ='1획지'!Q14 -> 1019 | W26: ='2획지'!Q14 -> 2783.4 | X26: ='1획지'!R14 -> 1261.85 | Y26: ='2획지'!R14 -> 2806.04 | Z26: =X26-V26 -> 242.85 | AA26: =Y26-W26 -> 22.64
C27: 법정 | E27: =F24+F25+F26 -> 5158.3813 | G27: =R22/134 -> 28.252537 | I27: =SUM(E27:H27) -> 5186.6338 | L27: 통신시설 | N27: 구내 통신 선로 설비(초고속정보통신),경비실 통화전화 | R27: 설치(홈네트워크) | U27: 주민운동시설 | X27: ='1획지'!R16 -> 1200 | Y27: ='2획지'!R16 -> 1200 | Z27: =X27-V27 -> 1200 | AA27: =Y27-W27 -> 1200
C28: 계획 | E28: ='1획지'!E28+'2획지'!E28 -> 8162 | G28: =SUM(G30:H31) -> 37 | I28: =SUM(E28:H28) -> 8199 | J28: =J31+J30 -> 1 | L28: 보안등 | N28: 50m이내마다 설치 | R28: 설치 | U28: 소계 | V28: =SUM(V25:V27) -> 1349 | W28: =SUM(W25:W27) -> 3760.8 | X28: =SUM(X25:X27) -> 2910.11 | Y28: =SUM(Y25:Y27) -> 5064.4472 | Z28: =SUM(Z25:Z27) -> 1561.11 | AA28: =SUM(AA25:AA27) -> 1303.6472
E29: =E28/C65 -> 2 | G29: =G28/G27 -> 1.3096169 | L29: 가스공급시설 | N29: 세대마다 도시가스 공급시설 | R29: 설치 | U29: 총합(B) | W29: =V28+W28 -> 5109.8 | Y29: =X28+Y28 -> 7974.5572 | AA29: =Z28+AA28 -> 2864.7572
C30: 지상주차 | L30: 비상급수시설 | N30: 세대당 0.5톤 | R30: 설치 | U30: 총합(A+B) | W30: =W21+W29 -> 7131.4 | Y30: =Y21+Y29 -> 12771.267 | AA30: =AA21+AA29 -> 5639.8667
C31: 지하주차 | E31: =C65*2 -> 8162 | G31: ='1획지'!G31+'2획지'!G31 -> 37 | I31: =SUM(E31:H31) -> 8199 | J31: =I31/I28 -> 1 | L31: 페기물보관시설 | N31: 생활폐기물 보관시설 또는 용기설치 | R31: 설치
B32: 구 조 | E32: 철근콘크리트 구조 | L32: 전기시설 | N32: 세대별 3kW+(전용60m² 초과하는 10m²마다 0.5kW더한값) | R32: 설치 | U32: 인센티브 | V32: =210%*(AA30/W30)*0.1 -> 0.16607847
B33: 조 경 면 적 | E33: =E13*0.3 -> 49611.6 | G33: =E33/E13 -> 0.3 | L33: TV공청시설 | N33: 공동시청 안테나 설치, 각 세대 단자 2개소 이상 | R33: 설치
C34: 기부채납임대 | E34: ='1획지'!E34+'2획지'!E34 -> 2312.3112 | L34: 승강기 | N34: 4층이상인 층의 세대당 0.3인 비율로 산정한 인원수 이상 | R34: 설치 | U34: 돌봄시설인센티브 | V34: =(Y21-W21)/Q10*210*0.1 -> 5.1393749
B35: 임대주택 | E35: =J50/E13 -> 0.25085181 | I35: 상한용적률 250.00%적용
E36: =J50 -> 41483.865
B37: 비 고 | L37: 비고
B40: ■단위세대 면적표
B42: 주택형별 | C42: 세대수 | E42: 비율 | F42: 전용면적 | G42: 주거공용면적 | J42: 분양면적 | M42: 기타공용 | P42: 지하주차장 | R42: 계약면적 | S42: 비고
G43: 벽체공용 | H43: 코아공용 | I43: 소계 | M43: 부대시설 | N43: 기전실 | O43: 소계 | T43: 대지지분 | W43: 주거 전용면적소계 | Y43: =F65 -> 360191.71 | Z43: =E13/Y49*Y43 -> 158015.5 | AA43: =Z43/F65 -> 0.43869833
B44: 59㎡(기채) | C44: ='1획지'!C44+'2획지'!C44 -> 21 | F44: 59.94 | G44: 7.04 | H44: =F44*0.24 -> 14.3856 | I44: =G44+H44 -> 21.4256 | J44: =F44+I44 -> 81.3656 | L44: =J44*0.3025 -> 24.613094 | M44: =(F44/F$65)*M$65 -> 2.1605334 | N44: =(F44/F$65)*N$65 -> 0.50934364 | O44: =SUM(M44:N44) -> 2.669877 | P44: =(F44/F$65)*P$65 -> 58.533057 | R44: =J44+O44+P44 -> 142.56853
B45: 74㎡(기채) | C45: ='1획지'!C45+'2획지'!C45 -> 6 | F45: 74.94 | G45: 7.68 | H45: =F45*0.24 -> 17.9856 | I45: =G45+H45 -> 25.6656 | J45: =F45+I45 -> 100.6056 | L45: =J45*0.3025 -> 30.433194 | M45: =(F45/F$65)*M$65 -> 2.7012074 | N45: =(F45/F$65)*N$65 -> 0.63680701 | O45: =SUM(M45:N45) -> 3.3380144 | P45: =(F45/F$65)*P$65 -> 73.180969 | R45: =J45+O45+P45 -> 177.12458
...

Sheet 1획지
B2: 획지1
B3: ■설계개요 | L3: ■부대시설 및 복리시설
B5: 사 업 명 | E5: 목동 10단지 재건축사업 (1획지) | L5: 구분 | N5: 법적기준 및 설치기준 | R5: 계획 | S5: 비고
B6: 대 지 위 치 | E6: 서울시 양천구 신정동 310번지일대 | L6: 진입도로 | N6: 20m이상(1000세대이상) | Q6: 20m 도로 | R6: 15, 25m도로
B7: 지 역 지 구 | E7: 제1종/제3종일반주거지역, 지구단위계획구역 | L7: 단지내도로 | N7: 7m이상 도로(7m이상 도로 1.5m인도 설치) | Q7: 7m 도로 | R7: 10m도로
B8: 용 도 | E8: 공동주택, 부대시설, 근린생활시설 | L8: 관리사무소 | N8: 50세대 이상: 10m²+(세대수-50) X 0.05m² | Q8: =10+(C65-50)*0.05 -> 48.45 | R8: 261.58
B9: 도 로 현 황 | E9: 북,동,서측 15m도로, 남측 25m, 단지통과 15m도로
B10: 사업부지면적 | L10: 주민공동시설 | N10: 100이상 1,000세대 미만 : 세대당 2.5㎡x1.25 | Q10: =(C65*2.5)*1.25 -> 2559.375 | R10: =SUM(R13:R21) -> 3717.99 | T10: =R10/C65 -> 4.5396703
B11: 기반시설 | C11: 공원,사회복지시설,경제시설 | T11: =T10*0.3025 -> 1.3732503
C12: 도로, 유치원, 녹지,하수도
B13: 1획지 공동주택부지면적 | E13: 32320.6 | G13: =E13*0.3025 -> 9776.9815 | L13: 1 | M13: 경로당 | N13: 500~1000세대 미만 | Q13: 330 | R13: 448.26 | T13: =R13+R8+R15+R17+R18+R19+R20+R21+R24 -> 1538.72
A14: =(299.99%-E20)*E13 -> 12.81674 | B14: 건 축 면 적 | E14: 7180.0672 | L14: 2 | M14: 어린이놀이터 | N14: 300~1,000세대 미만: 200㎡+세대당1㎡ | Q14: =200+C65*1 -> 1019 | R14: 1261.85 | T14: =T13/C65 -> 1.878779
B15: 건 폐 율 | E15: =E14/E13 -> 0.22215142 | L15: 3 | M15: 어린이집 | N15: 500~1000세대 미만 | Q15: 330 | R15: 378.12
B16: 연면적 | C16: 지상 연면적 | E16: =J65+R13+R8+R15+R17+R20+R24+R18+R22+R19 -> 96945.751 | G16: =E16*0.3025 -> 29326.09 | L16: 4 | M16: 주민운동시설 | N16: 500세대 이상 설치 | Q16: - | R16: 1200
C17: 지하 연면적 | E17: =R20+N65+P65+R23 -> 71080.156 | G17: =E17*0.3025 -> 21501.747 | L17: 5 | M17: 작은도서관 | N17: 500~1000세대 미만 | Q17: 158 | R17: 214.88
C18: 전체 연면적 | E18: =E16+E17 -> 168025.91 | G18: =E18*0.3025 -> 50827.837 | L18: 6 | M18: 다함께돌봄센터 | N18: 500세대 이상 설치, 최소 66㎡ 이상 | Q18: 66 | R18: 214.88
B19: 용적률 산정연면적 | E19: =E16 -> 96945.751 | L19: 7 | M19: 우리동네키움센터 | Q19: -
B20: 용 적 률 | E20: =E19/E13 -> 2.9995034 | I20: 법정 : 300.00% | L20: 8 | M20: 주민공동시설 | Q20: -
B21: 건 축 규 모 | Q21: -
B22: 건 물 높 이 | L22: 근린생활시설 | Q22: 지상 | R22: ='개요(전체)_발송'!G84 -> 396.48 | S22: 상가
C23: 용도 | E23: 아파트 | G23: 근린생활시설 | I23: 합계 | J23: 비율 | Q23: 지하 | R23: ='개요(전체)_발송'!G86 -> 195.7056 | S23: 기전기실+주차
B24: 주차대수 | C24: 산출근거 | E24: 60이하 세대당 0.8대 | F24: =(C47+C54+C44)*0.8 -> 227.2 | G24: 시설면적 134m²당 1대 | L24: 경비실 | N24: 1개소 | Q24: - | R24: 21
E25: 85이하 75m² 당 1대 | F25: =SUMPRODUCT(C55:C58,F55:F58)/75+C48*F48/75+C45*F45/75+C49*F49/75 -> 262.924 | L25: 국기게양대 | N25: 세대당 1개소 설치 | R25: 설치
E26: 85초과 65m² 당 1대 | F26: =SUMPRODUCT(C59:C63,F59:F63)/65 -> 519.32492 | L26: 안내표지판 | N26: 300세대 이상, 안내표지판등 설치 | R26: 설치
C27: 법정 | E27: =F24+F25+F26 -> 1009.4489 | G27: =R22/134 -> 2.958806 | I27: =SUM(E27:H27) -> 1012.4077 | L27: 통신시설 | N27: 구내 통신 선로 설비(초고속정보통신),경비실 통화전화 | R27: 설치(홈네트워크)
C28: 계획 | E28: =SUM(E30:F31) -> 1638 | G28: =G30+G31 -> 4 | I28: =SUM(E28:H28) -> 1642 | J28: =J31+J30 -> 1 | L28: 보안등 | N28: 50m이내마다 설치 | R28: 설치
E29: =E28/C65 -> 2 | G29: =G28/G27 -> 1.3518967 | L29: 가스공급시설 | N29: 세대마다 도시가스 공급시설 | R29: 설치
C30: 지상주차 | L30: 비상급수시설 | N30: 세대당 0.5톤 | R30: 설치
C31: 지하주차 | E31: =C65*2 -> 1638 | G31: 4 | I31: =SUM(E31:H31) -> 1642 | J31: =I31/I28 -> 1 | L31: 페기물보관시설 | N31: 생활폐기물 보관시설 또는 용기설치 | R31: 설치
B32: 구 조 | E32: 철근콘크리트 구조 | L32: 전기시설 | N32: 세대별 3kW+(전용60m² 초과하는 10m²마다 0.5kW더한값) | R32: 설치
B33: 조 경 면 적 | E33: =E13*0.3 -> 9696.18 | G33: =E33/E13 -> 0.3 | L33: TV공청시설 | N33: 공동시청 안테나 설치, 각 세대 단자 2개소 이상 | R33: 설치
C34: 기부채납임대 | E34: =J46 -> 507.4336 | L34: 승강기 | N34: 4층이상인 층의 세대당 0.3인 비율로 산정한 인원수 이상 | R34: 설치
B35: 임대주택 | E35: =J50/E13 -> 0.25099233 | I35: 0.25
E36: =J50 -> 8112.2228 | I36: =E13*I35 -> 8080.15
B37: 비 고 | L37: 비고
B40: ■단위세대 면적표
B42: 주택형별 | C42: 세대수 | E42: 비율 | F42: 전용면적 | G42: 주거공용면적 | J42: 분양면적 | M42: 기타공용 | P42: 지하주차장 | R42: 계약면적 | S42: 비고
G43: 벽체공용 | H43: 코아공용 | I43: 소계 | M43: 부대시설 | N43: 기전실 | O43: 소계
B44: 59㎡(기채) | C44: 5 | F44: 59.94 | G44: 7.04 | H44: =F44*0.24 -> 14.3856 | I44: =G44+H44 -> 21.4256 | J44: =F44+I44 -> 81.3656 | L44: =J44*0.3025 -> 24.613094 | M44: =(F44/F$65)*M$65 -> 1.3082694 | N44: =(F44/F$65)*N$65 -> 0.52225519 | O44: =SUM(M44:N44) -> 1.8305246 | P44: =(F44/F$65)*P$65 -> 59.745994 | R44: =J44+O44+P44 -> 142.94212
B45: 74㎡(기채) | C45: 1 | F45: 74.94 | G45: 7.68 | H45: =F45*0.24 -> 17.9856 | I45: =G45+H45 -> 25.6656 | J45: =F45+I45 -> 100.6056 | L45: =J45*0.3025 -> 30.433194 | M45: =(F45/F$65)*M$65 -> 1.6356642 | N45: =(F45/F$65)*N$65 -> 0.65294968 | O45: =SUM(M45:N45) -> 2.2886139 | P45: =(F45/F$65)*P$65 -> 74.697444 | R45: =J45+O45+P45 -> 177.59166
...

Sheet 2획지
B2: 획지2
B3: ■설계개요 | L3: ■부대시설 및 복리시설
B5: 사 업 명 | E5: 목동 10단지 재건축사업 (2획지) | L5: 구분 | N5: 법적기준 및 설치기준 | R5: 계획 | S5: 비고
B6: 대 지 위 치 | E6: 서울시 양천구 신정동 310번지일대 | L6: 진입도로 | N6: 20m이상(1000세대이상) | Q6: 20m 도로 | R6: 15, 25m도로
B7: 지 역 지 구 | E7: 제1종/제3종일반주거지역, 지구단위계획구역 | L7: 단지내도로 | N7: 7m이상 도로(7m이상 도로 1.5m인도 설치) | Q7: 7m 도로 | R7: 10m도로
B8: 용 도 | E8: 공동주택, 부대시설, 근린생활시설 | L8: 관리사무소 | N8: 50세대 이상, 10m²+(세대수-50) X 0.05m² | Q8: =10+(C65-50)*0.05 -> 170.6 | R8: 313.13 | S8: MDF/방재실포함
B9: 도 로 현 황 | E9: 북,동,서측 15m도로, 남측 25m, 단지통과 15m도로 | L9: 유치원 | N9: 2,000세대 이상 | Q9: - | S9: 현시설이동
B10: 사업부지면적 | L10: 주민공동시설 | N10: 1,000세대 이상 : 500+(세대수x2㎡)x1.25 | Q10: =(500+(C65*2))*1.25 -> 8780 | R10: =SUM(R13:R21) -> 15053.277 | T10: =R10/C65 -> 4.6147384
B11: 기반시설 | C11: 공원,사회복지시설,경제시설 | T11: =T10*0.3025 -> 1.3959584
C12: 도로, 유치원, 녹지,하수도
B13: 2획지 공동주택부지면적 | E13: 133051.4 | G13: =E13*0.3025 -> 40248.048 | L13: 1 | M13: 경로당 | N13: 1500세대 이상 | Q13: =725+(C65-2000)*0.2 -> 977.4 | R13: 1058.4072 | T13: =R13+R8+R15+R17+R18+R19+R20+R21+R24 -> 11444.367
B14: 건 축 면 적 | E14: 29250.801 | L14: 2 | M14: 어린이놀이터 | N14: 1000세대 이상:500㎡+세대당0.7㎡ | Q14: =500+C65*0.7 -> 2783.4 | R14: 2806.04 | T14: =T13/C65 -> 3.5083895
B15: 건 폐 율 | E15: =E14/E13 -> 0.21984587 | L15: 3 | M15: 어린이집 | N15: 1500세대 이상 | Q15: =725+(C65-2000)*0.2 -> 977.4 | R15: 1188
B16: 연면적 | C16: 지상 연면적 | E16: =J65+R13+R8+R15+R17+R19+R24+R18+R22+R20 -> 398973.84 | G16: =E16*0.3025 -> 120689.59 | L16: 4 | M16: 주민운동시설 | N16: 500세대 이상 설치 | Q16: - | R16: 1200 | S16: 외부
C17: 지하 연면적 | E17: =R21+N65+P65+R23 -> 289939.79 | G17: =E17*0.3025 -> 87706.788 | L17: 5 | M17: 작은도서관 | N17: 1500세대 이상 | Q17: =298+(C65-2000)*0.1 -> 424.2 | R17: 630.68
C18: 전체 연면적 | E18: =E16+E17 -> 688913.63 | G18: =E18*0.3025 -> 208396.37 | L18: 6 | M18: 다함께돌봄센터 | N18: 500세대 이상 설치, 최소 66㎡ 이상 | Q18: 66 | R18: =534.2964+657.6831-R19 -> 741.9795
B19: 용적률 산정연면적 | E19: =E16 -> 398973.84 | L19: 7 | M19: 우리동네키움센터 | N19: - | Q19: - | R19: 450 | U19: 실내어린이놀이터
A20: =(299.99%-E20)*E13 -> 167.05896 | B20: 용 적 률 | E20: =E19/E13 -> 2.9986444 | I20: 법정 : 300.00% | L20: 8 | M20: 주민공동시설 | N20: 실내놀이터 | Q20: - | R20: 978.17 | U20: =R20 -> 978.17
B21: 건 축 규 모 | N21: 주민운동시설 | Q21: - | R21: 6000 | S21: 지하
B22: 건 물 높 이 | L22: 근린생활시설 | Q22: 지상 | R22: ='개요(전체)_발송'!G96+'개요(전체)_발송'!G105 -> 3389.36 | S22: 상가
C23: 용도 | E23: 아파트 | G23: 근린생활시설 | I23: 합계 | J23: 비율 | Q23: 지하 | R23: ='개요(전체)_발송'!G98+'개요(전체)_발송'!G107 -> 1613.6936 | S23: 기전기실+주차
B24: 주차대수 | C24: 산출근거 | E24: 60이하 세대당 0.8대 | F24: =(C47+C54+C44)*0.8 -> 744 | G24: 시설면적 134m²당 1대 | L24: 경비실 | N24: 4개소 | Q24: - | R24: 84
E25: 85이하 75m² 당 1대 | F25: =SUMPRODUCT(C55:C58,F55:F58)/75+C48*F48/75+C45*F45/75+C49*F49/75 -> 1262.8525 | L25: 국기게양대 | N25: 세대당 1개소 설치 | R25: 설치
E26: 85초과 65m² 당 1대 | F26: =SUMPRODUCT(C59:C63,F59:F63)/65 -> 2142.0798 | L26: 안내표지판 | N26: 300세대 이상, 안내표지판등 설치 | R26: 설치
C27: 법정 | E27: =F24+F25+F26 -> 4148.9324 | G27: =R22/134 -> 25.293731 | I27: =SUM(E27:H27) -> 4174.2261 | L27: 통신시설 | N27: 구내 통신 선로 설비(초고속정보통신),경비실 통화전화 | R27: 설치(홈네트워크)
C28: 계획 | E28: =SUM(E30:F31) -> 6524 | G28: =G30+G31 -> 33 | I28: =SUM(E28:H28) -> 6557 | J28: =J31+J30 -> 1 | L28: 보안등 | N28: 50m이내마다 설치 | R28: 설치
E29: =E28/C65 -> 2 | G29: =G28/G27 -> 1.3046711 | L29: 가스공급시설 | N29: 세대마다 도시가스 공급시설 | R29: 설치
C30: 지상주차 | L30: 비상급수시설 | N30: 세대당 0.5톤 | R30: 설치
C31: 지하주차 | E31: =C65*2 -> 6524 | G31: ='개요(전체)_발송'!J100+'개요(전체)_발송'!J109 -> 33 | I31: =SUM(E31:H31) -> 6557 | J31: =I31/I28 -> 1 | L31: 페기물보관시설 | N31: 생활폐기물 보관시설 또는 용기설치 | R31: 설치
B32: 구 조 | E32: 철근콘크리트 구조 | L32: 전기시설 | N32: 세대별 3kW+(전용60m² 초과하는 10m²마다 0.5kW더한값) | R32: 설치
B33: 조 경 면 적 | E33: =E13*0.3 -> 39915.42 | G33: =E33/E13 -> 0.3 | L33: TV공청시설 | N33: 공동시청 안테나 설치, 각 세대 단자 2개소 이상 | R33: 설치
C34: 기부채납임대 | E34: =J46 -> 1804.8776 | L34: 승강기 | N34: 4층이상인 층의 세대당 0.3인 비율로 산정한 인원수 이상 | R34: 설치
B35: 임대주택 | E35: =J50/E13 -> 0.25081767 | I35: 0.25
E36: =J50 -> 33371.642 | I36: =I35*E13 -> 33262.85
B37: 비 고 | L37: 비고
B40: ■단위세대 면적표
B42: 주택형별 | C42: 세대수 | E42: 비율 | F42: 전용면적 | G42: 주거공용면적 | J42: 분양면적 | M42: 기타공용 | P42: 지하주차장 | R42: 계약면적 | S42: 비고
G43: 벽체공용 | H43: 코아공용 | I43: 소계 | M43: 부대시설 | N43: 기전실 | O43: 소계
B44: 59㎡(기채) | C44: 16 | E44: =C44/C46 -> 0.76190476 | F44: 59.94 | G44: 7.04 | H44: =F44*0.24 -> 14.3856 | I44: =G44+H44 -> 21.4256 | J44: =F44+I44 -> 81.3656 | L44: =J44*0.3025 -> 24.613094 | M44: =(F44/F$65)*M$65 -> 2.3679363 | N44: =(F44/F$65)*N$65 -> 0.50620154 | O44: =SUM(M44:N44) -> 2.8741378 | P44: =(F44/F$65)*P$65 -> 57.909456 | R44: =J44+O44+P44 -> 142.14919
B45: 74㎡(기채) | C45: 5 | E45: =C45/C46 -> 0.23809524 | F45: 74.94 | G45: 7.68 | H45: =F45*0.24 -> 17.9856 | I45: =G45+H45 -> 25.6656 | J45: =F45+I45 -> 100.6056 | L45: =J45*0.3025 -> 30.433194 | M45: =(F45/F$65)*M$65 -> 2.9605129 | N45: =(F45/F$65)*N$65 -> 0.6328786 | O45: =SUM(M45:N45) -> 3.5933915 | P45: =(F45/F$65)*P$65 -> 72.401312 | R45: =J45+O45+P45 -> 176.6003
...

Sheet 분양수입변동
B2: 정비계획안
C3: 전체 | D3: 조합원 | E3: 일반분양 | F3: 분양평형 | G3: 평당분양가
B4: 59㎡ | C4: 638 | E4: =C4-D4 -> 638 | F4: ='개요(전체)_발송'!F122 -> 24.613094 | G4: 56213 | H4: =E4*F4*G4 -> 8.8272139e+08
B5: 74㎡ | C5: 336 | E5: =C5-D5 -> 336 | F5: ='개요(전체)_발송'!F123 -> 30.433194 | G5: 55142 | H5: =E5*F5*G5 -> 5.6385745e+08
B6: 84㎡ | C6: 1079 | D6: 672 | E6: =C6-D6 -> 407 | F6: ='개요(전체)_발송'!F124 -> 34.383723 | G6: 53536 | H6: =E6*F6*G6 -> 7.4919217e+08
B7: 99㎡ | C7: 490 | D7: 490 | E7: =C7-D7 -> 0 | F7: ='개요(전체)_발송'!F125 -> 40.480913 | G7: 53536 | H7: =E7*F7*G7 -> 0
B8: 112㎡ | C8: 564 | D8: 564 | E8: =C8-D8 -> 0 | F8: ='개요(전체)_발송'!F126 -> 45.860815 | G8: 53536 | H8: =E8*F8*G8 -> 0
B9: 129㎡ | C9: 282 | D9: 282 | E9: =C9-D9 -> 0 | F9: ='개요(전체)_발송'!F127 -> 52.87337 | G9: 53536 | H9: =E9*F9*G9 -> 0
B10: 159㎡ | C10: 152 | D10: 152 | E10: =C10-D10 -> 0 | F10: ='개요(전체)_발송'!L62 -> 65.28918 | G10: 53536 | H10: =E10*F10*G10 -> 0
B11: 소 계 | C11: =SUM(C4:C10) -> 3541 | D11: =SUM(D4:D10) -> 2160 | E11: =SUM(E4:E10) -> 1381 | H11: =SUM(H4:H10) -> 2.195771e+09
B14: 현재계획안
C15: 전체 | D15: 조합원 | E15: 일반분양
B16: 59㎡ | C16: ='개요(전체)_발송'!C122 -> 805 | D16: 0 | E16: =C16-D16 -> 805 | F16: =F4 -> 24.613094 | G16: 56213 | H16: =E16*F16*G16 -> 1.1137786e+09 | J16: 8 | K16: 6 | L16: 7 | M16: =SUM(J16:L16) -> 21 | N16: 7
B17: 74㎡ | C17: ='개요(전체)_발송'!C123 -> 167 | D17: 0 | E17: =C17-D17 -> 167 | F17: =F5 -> 30.433194 | G17: 55142 | H17: =E17*F17*G17 -> 2.8025058e+08 | K17: 6
B18: 84㎡ | C18: ='개요(전체)_발송'!C124 -> 1107 | D18: 672 | E18: =C18-D18 -> 435 | F18: =F6 -> 34.383723 | G18: 53536 | H18: =E18*F18*G18 -> 8.0073364e+08 | J18: 8
B19: 99㎡ | C19: ='개요(전체)_발송'!C125 -> 497 | D19: 490 | E19: =C19-D19 -> 7 | F19: =F7 -> 40.480913 | G19: 53536 | H19: =E19*F19*G19 -> 15170303
B20: 112㎡ | C20: ='개요(전체)_발송'!C126 -> 580 | D20: 564 | E20: =C20-D20 -> 16 | F20: =F8 -> 45.860815 | G20: 53536 | H20: =E20*F20*G20 -> 39283273
B21: 129㎡ | C21: ='개요(전체)_발송'!C127 -> 272 | D21: 282 | E21: =C21-D21 -> -10 | F21: =F9 -> 52.87337 | G21: 53536 | H21: =E21*F21*G21 -> -28306287
B22: 159㎡ | C22: ='개요(전체)_발송'!C128 -> 140 | D22: 152 | E22: =C22-D22 -> -12 | F22: =F10 -> 65.28918 | G22: 53536 | H22: =E22*F22*G22 -> -41943858
B23: 192㎡ | C23: ='개요(전체)_발송'!C129 -> 4 | D23: 0 | E23: =C23-D23 -> 4 | F23: ='개요(전체)_발송'!L63 -> 77.68442 | G23: 53536 | H23: =E23*F23*G23 -> 16635652
B24: 소 계 | C24: =SUM(C16:C23) -> 3572 | D24: =SUM(D16:D23) -> 2160 | E24: =SUM(E16:E23) -> 1412 | H24: =SUM(H16:H23) -> 2.1956019e+09
H25: =H24-H11 -> -169147.55
B27: 조합원 | E27: 일반분양
B28: 정비계획 | C28: 현재 | D28: 차 | E28: 정비계획 | F28: 현재 | G28: 차
A29: 59㎡ | B29: =D4 -> 0 | C29: =D16 -> 0 | D29: =C29-B29 -> 0 | E29: =E4 -> 638 | F29: =E16 -> 805 | G29: =F29-E29 -> 167
A30: 74㎡ | B30: =D5 -> 0 | C30: =D17 -> 0 | D30: =C30-B30 -> 0 | E30: =E5 -> 336 | F30: =E17 -> 167 | G30: =F30-E30 -> -169
A31: 84㎡ | B31: =D6 -> 672 | C31: =D18 -> 672 | D31: =C31-B31 -> 0 | E31: =E6 -> 407 | F31: =E18 -> 435 | G31: =F31-E31 -> 28
A32: 99㎡ | B32: =D7 -> 490 | C32: =D19 -> 490 | D32: =C32-B32 -> 0 | E32: =E7 -> 0 | F32: =E19 -> 7 | G32: =F32-E32 -> 7
A33: 112㎡ | B33: =D8 -> 564 | C33: =D20 -> 564 | D33: =C33-B33 -> 0 | E33: =E8 -> 0 | F33: =E20 -> 16 | G33: =F33-E33 -> 16
A34: 129㎡ | B34: =D9 -> 282 | C34: =D21 -> 282 | D34: =C34-B34 -> 0 | E34: =E9 -> 0 | F34: =E21 -> -10 | G34: =F34-E34 -> -10
A35: 159㎡ | B35: =D10 -> 152 | C35: =D22 -> 152 | D35: =C35-B35 -> 0 | E35: =E10 -> 0 | F35: =E22 -> -12 | G35: =F35-E35 -> -12
A36: 192㎡ | C36: =D23 -> 0 | E36: 0 | F36: =E23 -> 4 | G36: =F36-E36 -> 4
A37: 소 계 | B37: =SUM(B29:B36) -> 2160 | C37: =SUM(C29:C36) -> 2160 | D37: =SUM(D29:D36) -> 0 | E37: =SUM(E29:E36) -> 1381 | F37: =SUM(F29:F36) -> 1412 | G37: =SUM(G29:G36) -> 31
